2025-08-07 12:12:17 | error | WARNING | Error response: {
  "method": "GET",
  "url": "http://localhost:8000/api/v1/auth/me",
  "status_code": 401,
  "duration_ms": 83.17,
  "client_ip": "127.0.0.1",
  "user_id": null
}
2025-08-07 12:18:20 | error | WARNING | Error response: {
  "method": "GET",
  "url": "http://localhost:8000/api/v1/health",
  "status_code": 404,
  "duration_ms": 0.0,
  "client_ip": "127.0.0.1",
  "user_id": null
}
2025-08-07 12:19:26 | error | WARNING | Error response: {
  "method": "GET",
  "url": "http://localhost:8000/api/v1/vendors/",
  "status_code": 403,
  "duration_ms": 1.13,
  "client_ip": "127.0.0.1",
  "user_id": null
}
2025-08-07 12:19:37 | error | WARNING | Error response: {
  "method": "POST",
  "url": "http://localhost:8000/api/v1/vendors/public-registration",
  "status_code": 422,
  "duration_ms": 4.94,
  "client_ip": "127.0.0.1",
  "user_id": null
}
2025-08-07 12:20:47 | error | WARNING | Error response: {
  "method": "GET",
  "url": "http://localhost:8000/api/v1/vendors/public-registration",
  "status_code": 403,
  "duration_ms": 0.0,
  "client_ip": "127.0.0.1",
  "user_id": null
}
2025-08-07 12:20:49 | error | WARNING | Error response: {
  "method": "POST",
  "url": "http://localhost:8000/api/v1/vendors/public-registration",
  "status_code": 422,
  "duration_ms": 0.0,
  "client_ip": "127.0.0.1",
  "user_id": null
}
2025-08-07 12:21:41 | error | WARNING | Error response: {
  "method": "GET",
  "url": "http://localhost:8000/api/v1/vendors/public-registration",
  "status_code": 403,
  "duration_ms": 3.0,
  "client_ip": "127.0.0.1",
  "user_id": null
}
2025-08-07 12:39:56 | error | WARNING | Error response: {
  "method": "GET",
  "url": "http://localhost:8000/api/v1/vendors/",
  "status_code": 403,
  "duration_ms": 6.94,
  "client_ip": "127.0.0.1",
  "user_id": null
}
2025-08-07 12:40:01 | error | WARNING | Error response: {
  "method": "GET",
  "url": "http://localhost:8000/api/v1/vendors/",
  "status_code": 403,
  "duration_ms": 8.99,
  "client_ip": "127.0.0.1",
  "user_id": null
}
2025-08-07 12:40:23 | error | WARNING | Error response: {
  "method": "GET",
  "url": "http://localhost:8000/api/v1/vendors/?status=pending",
  "status_code": 403,
  "duration_ms": 10.33,
  "client_ip": "127.0.0.1",
  "user_id": null
}
2025-08-07 12:40:25 | error | WARNING | Error response: {
  "method": "GET",
  "url": "http://localhost:8000/api/v1/vendors/?status=pending",
  "status_code": 403,
  "duration_ms": 9.0,
  "client_ip": "127.0.0.1",
  "user_id": null
}
2025-08-07 12:40:28 | error | WARNING | Error response: {
  "method": "GET",
  "url": "http://localhost:8000/api/v1/vendors/?status=pending",
  "status_code": 403,
  "duration_ms": 2.51,
  "client_ip": "127.0.0.1",
  "user_id": null
}
2025-08-07 12:40:32 | error | WARNING | Error response: {
  "method": "GET",
  "url": "http://localhost:8000/api/v1/vendors/",
  "status_code": 403,
  "duration_ms": 3.0,
  "client_ip": "127.0.0.1",
  "user_id": null
}
2025-08-07 12:40:43 | error | WARNING | Error response: {
  "method": "GET",
  "url": "http://localhost:8000/api/v1/vendors/?status=pending",
  "status_code": 403,
  "duration_ms": 8.71,
  "client_ip": "127.0.0.1",
  "user_id": null
}
2025-08-07 12:40:45 | error | WARNING | Error response: {
  "method": "GET",
  "url": "http://localhost:8000/api/v1/vendors/",
  "status_code": 403,
  "duration_ms": 10.38,
  "client_ip": "127.0.0.1",
  "user_id": null
}
2025-08-07 12:40:47 | error | WARNING | Error response: {
  "method": "GET",
  "url": "http://localhost:8000/api/v1/vendors/?status=pending",
  "status_code": 403,
  "duration_ms": 2.74,
  "client_ip": "127.0.0.1",
  "user_id": null
}
2025-08-07 12:40:48 | error | WARNING | Error response: {
  "method": "GET",
  "url": "http://localhost:8000/api/v1/vendors/",
  "status_code": 403,
  "duration_ms": 7.23,
  "client_ip": "127.0.0.1",
  "user_id": null
}
2025-08-07 12:40:50 | error | WARNING | Error response: {
  "method": "GET",
  "url": "http://localhost:8000/api/v1/vendors/",
  "status_code": 403,
  "duration_ms": 2.81,
  "client_ip": "127.0.0.1",
  "user_id": null
}
2025-08-07 12:41:48 | error | WARNING | Error response: {
  "method": "GET",
  "url": "http://localhost:8000/api/v1/vendors/public-registration",
  "status_code": 403,
  "duration_ms": 8.31,
  "client_ip": "127.0.0.1",
  "user_id": null
}
2025-08-07 12:42:04 | error | WARNING | Error response: {
  "method": "GET",
  "url": "http://localhost:8000/api/v1/vendors/11",
  "status_code": 403,
  "duration_ms": 3.54,
  "client_ip": "127.0.0.1",
  "user_id": null
}
2025-08-07 12:42:27 | error | WARNING | Error response: {
  "method": "GET",
  "url": "http://localhost:8000/api/v1/auth/me",
  "status_code": 401,
  "duration_ms": 4.0,
  "client_ip": "127.0.0.1",
  "user_id": null
}
2025-08-07 12:43:10 | error | WARNING | Error response: {
  "method": "GET",
  "url": "http://localhost:8000/api/v1/vendors/",
  "status_code": 403,
  "duration_ms": 6.36,
  "client_ip": "127.0.0.1",
  "user_id": null
}
2025-08-07 12:43:12 | error | WARNING | Error response: {
  "method": "GET",
  "url": "http://localhost:8000/api/v1/vendors/",
  "status_code": 403,
  "duration_ms": 6.62,
  "client_ip": "127.0.0.1",
  "user_id": null
}
2025-08-07 12:43:21 | error | WARNING | Error response: {
  "method": "GET",
  "url": "http://localhost:8000/api/v1/vendors/",
  "status_code": 403,
  "duration_ms": 2.92,
  "client_ip": "127.0.0.1",
  "user_id": null
}
2025-08-07 12:43:22 | error | WARNING | Error response: {
  "method": "GET",
  "url": "http://localhost:8000/api/v1/vendors/",
  "status_code": 403,
  "duration_ms": 4.36,
  "client_ip": "127.0.0.1",
  "user_id": null
}
2025-08-07 12:43:23 | error | WARNING | Error response: {
  "method": "GET",
  "url": "http://localhost:8000/api/v1/vendors/?status=pending",
  "status_code": 403,
  "duration_ms": 2.0,
  "client_ip": "127.0.0.1",
  "user_id": null
}
2025-08-07 12:43:24 | error | WARNING | Error response: {
  "method": "GET",
  "url": "http://localhost:8000/api/v1/vendors/",
  "status_code": 403,
  "duration_ms": 4.0,
  "client_ip": "127.0.0.1",
  "user_id": null
}
2025-08-07 12:43:26 | error | WARNING | Error response: {
  "method": "GET",
  "url": "http://localhost:8000/api/v1/vendors/?status=pending",
  "status_code": 403,
  "duration_ms": 1.99,
  "client_ip": "127.0.0.1",
  "user_id": null
}
2025-08-07 12:43:26 | error | WARNING | Error response: {
  "method": "GET",
  "url": "http://localhost:8000/api/v1/vendors/",
  "status_code": 403,
  "duration_ms": 11.0,
  "client_ip": "127.0.0.1",
  "user_id": null
}
2025-08-07 12:43:59 | error | WARNING | Error response: {
  "method": "GET",
  "url": "http://localhost:8000/api/v1/vendors/",
  "status_code": 403,
  "duration_ms": 5.55,
  "client_ip": "127.0.0.1",
  "user_id": null
}
2025-08-07 12:44:19 | error | WARNING | Error response: {
  "method": "GET",
  "url": "http://localhost:8000/api/v1/vendors/",
  "status_code": 403,
  "duration_ms": 5.21,
  "client_ip": "127.0.0.1",
  "user_id": null
}
2025-08-07 12:44:47 | error | WARNING | Error response: {
  "method": "GET",
  "url": "http://localhost:8000/api/v1/vendors/",
  "status_code": 403,
  "duration_ms": 3.0,
  "client_ip": "127.0.0.1",
  "user_id": null
}
2025-08-07 12:45:12 | error | WARNING | Error response: {
  "method": "GET",
  "url": "http://localhost:8000/api/v1/vendors/",
  "status_code": 403,
  "duration_ms": 2.06,
  "client_ip": "127.0.0.1",
  "user_id": null
}
2025-08-07 12:45:39 | error | WARNING | Error response: {
  "method": "GET",
  "url": "http://localhost:8000/api/v1/vendors/",
  "status_code": 403,
  "duration_ms": 5.81,
  "client_ip": "127.0.0.1",
  "user_id": null
}
2025-08-07 12:47:16 | error | WARNING | Error response: {
  "method": "GET",
  "url": "http://localhost:8000/api/v1/vendors/",
  "status_code": 403,
  "duration_ms": 3.0,
  "client_ip": "127.0.0.1",
  "user_id": null
}
2025-08-07 12:47:33 | error | WARNING | Error response: {
  "method": "GET",
  "url": "http://localhost:8000/api/v1/vendors/",
  "status_code": 403,
  "duration_ms": 33.57,
  "client_ip": "127.0.0.1",
  "user_id": null
}
2025-08-07 12:48:49 | error | WARNING | Error response: {
  "method": "GET",
  "url": "http://localhost:8000/api/v1/vendors/",
  "status_code": 403,
  "duration_ms": 4.0,
  "client_ip": "127.0.0.1",
  "user_id": null
}
2025-08-07 12:48:51 | error | WARNING | Error response: {
  "method": "GET",
  "url": "http://localhost:8000/api/v1/vendors/",
  "status_code": 403,
  "duration_ms": 4.0,
  "client_ip": "127.0.0.1",
  "user_id": null
}
2025-08-07 12:48:52 | error | WARNING | Error response: {
  "method": "GET",
  "url": "http://localhost:8000/api/v1/vendors/?status=pending",
  "status_code": 403,
  "duration_ms": 8.66,
  "client_ip": "127.0.0.1",
  "user_id": null
}
2025-08-07 12:48:53 | error | WARNING | Error response: {
  "method": "GET",
  "url": "http://localhost:8000/api/v1/vendors/?status=pending",
  "status_code": 403,
  "duration_ms": 4.0,
  "client_ip": "127.0.0.1",
  "user_id": null
}
2025-08-07 12:48:54 | error | WARNING | Error response: {
  "method": "GET",
  "url": "http://localhost:8000/api/v1/vendors/?status=pending",
  "status_code": 403,
  "duration_ms": 3.0,
  "client_ip": "127.0.0.1",
  "user_id": null
}
2025-08-07 12:48:58 | error | WARNING | Error response: {
  "method": "GET",
  "url": "http://localhost:8000/api/v1/vendors/?status=pending",
  "status_code": 403,
  "duration_ms": 9.0,
  "client_ip": "127.0.0.1",
  "user_id": null
}
2025-08-07 12:49:08 | error | WARNING | Error response: {
  "method": "GET",
  "url": "http://localhost:8000/api/v1/vendors/?status=pending",
  "status_code": 403,
  "duration_ms": 4.04,
  "client_ip": "127.0.0.1",
  "user_id": null
}
2025-08-07 12:49:16 | error | WARNING | Error response: {
  "method": "GET",
  "url": "http://localhost:8000/api/v1/vendors/?status=pending",
  "status_code": 403,
  "duration_ms": 3.08,
  "client_ip": "127.0.0.1",
  "user_id": null
}
2025-08-07 12:50:43 | error | WARNING | Error response: {
  "method": "GET",
  "url": "http://localhost:8000/api/v1/vendors/?status=pending",
  "status_code": 403,
  "duration_ms": 2.0,
  "client_ip": "127.0.0.1",
  "user_id": null
}
2025-08-07 12:50:45 | error | WARNING | Error response: {
  "method": "GET",
  "url": "http://localhost:8000/api/v1/vendors/",
  "status_code": 403,
  "duration_ms": 2.01,
  "client_ip": "127.0.0.1",
  "user_id": null
}
2025-08-07 12:50:47 | error | WARNING | Error response: {
  "method": "GET",
  "url": "http://localhost:8000/api/v1/vendors/",
  "status_code": 403,
  "duration_ms": 2.0,
  "client_ip": "127.0.0.1",
  "user_id": null
}
2025-08-07 12:50:47 | error | WARNING | Error response: {
  "method": "GET",
  "url": "http://localhost:8000/api/v1/vendors/",
  "status_code": 403,
  "duration_ms": 3.02,
  "client_ip": "127.0.0.1",
  "user_id": null
}
2025-08-07 12:50:48 | error | WARNING | Error response: {
  "method": "GET",
  "url": "http://localhost:8000/api/v1/vendors/",
  "status_code": 403,
  "duration_ms": 2.1,
  "client_ip": "127.0.0.1",
  "user_id": null
}
2025-08-07 12:57:55 | error | WARNING | Error response: {
  "method": "GET",
  "url": "http://localhost:8000/api/v1/vendors/11",
  "status_code": 403,
  "duration_ms": 2.0,
  "client_ip": "127.0.0.1",
  "user_id": null
}
2025-08-07 12:57:58 | error | WARNING | Error response: {
  "method": "GET",
  "url": "http://localhost:8000/api/v1/vendors/11",
  "status_code": 403,
  "duration_ms": 2.42,
  "client_ip": "127.0.0.1",
  "user_id": null
}
2025-08-07 13:01:36 | error | WARNING | Error response: {
  "method": "GET",
  "url": "http://localhost:8000/api/v1/vendors/11",
  "status_code": 403,
  "duration_ms": 2.87,
  "client_ip": "127.0.0.1",
  "user_id": null
}
2025-08-07 13:01:39 | error | WARNING | Error response: {
  "method": "GET",
  "url": "http://localhost:8000/api/v1/vendors/11",
  "status_code": 403,
  "duration_ms": 2.29,
  "client_ip": "127.0.0.1",
  "user_id": null
}
2025-08-07 13:01:40 | error | WARNING | Error response: {
  "method": "GET",
  "url": "http://localhost:8000/api/v1/vendors/11",
  "status_code": 403,
  "duration_ms": 4.0,
  "client_ip": "127.0.0.1",
  "user_id": null
}
2025-08-07 13:10:38 | error | WARNING | Error response: {
  "method": "GET",
  "url": "http://localhost:8000/api/v1/vendors/7",
  "status_code": 403,
  "duration_ms": 2.0,
  "client_ip": "127.0.0.1",
  "user_id": null
}
2025-08-07 13:10:39 | error | WARNING | Error response: {
  "method": "GET",
  "url": "http://localhost:8000/api/v1/vendors/7",
  "status_code": 403,
  "duration_ms": 2.01,
  "client_ip": "127.0.0.1",
  "user_id": null
}
2025-08-07 13:10:41 | error | WARNING | Error response: {
  "method": "GET",
  "url": "http://localhost:8000/api/v1/vendors/7",
  "status_code": 403,
  "duration_ms": 1.43,
  "client_ip": "127.0.0.1",
  "user_id": null
}
2025-08-07 13:13:19 | error | WARNING | Error response: {
  "method": "GET",
  "url": "http://localhost:8000/api/v1/vendors/7",
  "status_code": 403,
  "duration_ms": 3.25,
  "client_ip": "127.0.0.1",
  "user_id": null
}
2025-08-07 13:13:20 | error | WARNING | Error response: {
  "method": "GET",
  "url": "http://localhost:8000/api/v1/vendors/7",
  "status_code": 403,
  "duration_ms": 3.36,
  "client_ip": "127.0.0.1",
  "user_id": null
}
2025-08-07 13:13:21 | error | WARNING | Error response: {
  "method": "GET",
  "url": "http://localhost:8000/api/v1/vendors/7",
  "status_code": 403,
  "duration_ms": 0.0,
  "client_ip": "127.0.0.1",
  "user_id": null
}
2025-08-07 13:13:40 | error | WARNING | Error response: {
  "method": "GET",
  "url": "http://localhost:8000/api/v1/vendors/11",
  "status_code": 403,
  "duration_ms": 2.0,
  "client_ip": "127.0.0.1",
  "user_id": null
}
2025-08-07 13:14:40 | error | WARNING | Error response: {
  "method": "GET",
  "url": "http://localhost:8000/api/v1/vendors/11",
  "status_code": 403,
  "duration_ms": 4.03,
  "client_ip": "127.0.0.1",
  "user_id": null
}
2025-08-07 13:14:55 | error | WARNING | Error response: {
  "method": "GET",
  "url": "http://localhost:8000/api/v1/vendors/11",
  "status_code": 403,
  "duration_ms": 1.0,
  "client_ip": "127.0.0.1",
  "user_id": null
}
2025-08-07 13:15:31 | error | WARNING | Error response: {
  "method": "GET",
  "url": "http://localhost:8000/api/v1/vendors/11",
  "status_code": 403,
  "duration_ms": 3.0,
  "client_ip": "127.0.0.1",
  "user_id": null
}
2025-08-07 13:15:33 | error | WARNING | Error response: {
  "method": "GET",
  "url": "http://localhost:8000/api/v1/vendors/11",
  "status_code": 403,
  "duration_ms": 3.37,
  "client_ip": "127.0.0.1",
  "user_id": null
}
2025-08-07 13:15:33 | error | WARNING | Error response: {
  "method": "GET",
  "url": "http://localhost:8000/api/v1/vendors/11",
  "status_code": 403,
  "duration_ms": 2.0,
  "client_ip": "127.0.0.1",
  "user_id": null
}
2025-08-07 13:15:34 | error | WARNING | Error response: {
  "method": "GET",
  "url": "http://localhost:8000/api/v1/vendors/11",
  "status_code": 403,
  "duration_ms": 2.0,
  "client_ip": "127.0.0.1",
  "user_id": null
}
2025-08-07 13:15:35 | error | WARNING | Error response: {
  "method": "GET",
  "url": "http://localhost:8000/api/v1/vendors/11",
  "status_code": 403,
  "duration_ms": 2.0,
  "client_ip": "127.0.0.1",
  "user_id": null
}
2025-08-07 13:15:36 | error | WARNING | Error response: {
  "method": "GET",
  "url": "http://localhost:8000/api/v1/vendors/11",
  "status_code": 403,
  "duration_ms": 2.01,
  "client_ip": "127.0.0.1",
  "user_id": null
}
2025-08-07 13:17:38 | error | WARNING | Error response: {
  "method": "GET",
  "url": "http://localhost:8000/api/v1/vendors/11",
  "status_code": 403,
  "duration_ms": 2.01,
  "client_ip": "127.0.0.1",
  "user_id": null
}
2025-08-07 13:17:39 | error | WARNING | Error response: {
  "method": "GET",
  "url": "http://localhost:8000/api/v1/vendors/11",
  "status_code": 403,
  "duration_ms": 3.0,
  "client_ip": "127.0.0.1",
  "user_id": null
}
2025-08-07 13:17:41 | error | WARNING | Error response: {
  "method": "GET",
  "url": "http://localhost:8000/api/v1/vendors/7",
  "status_code": 403,
  "duration_ms": 2.0,
  "client_ip": "127.0.0.1",
  "user_id": null
}
2025-08-07 13:17:43 | error | WARNING | Error response: {
  "method": "GET",
  "url": "http://localhost:8000/api/v1/vendors/7",
  "status_code": 403,
  "duration_ms": 2.0,
  "client_ip": "127.0.0.1",
  "user_id": null
}
2025-08-07 13:20:45 | error | WARNING | Error response: {
  "method": "GET",
  "url": "http://localhost:8000/api/v1/vendors/7/export/pdf",
  "status_code": 403,
  "duration_ms": 6.59,
  "client_ip": "127.0.0.1",
  "user_id": null
}
2025-08-07 14:11:05 | error | WARNING | Error response: {
  "method": "GET",
  "url": "http://localhost:8000/api/v1/auth/me",
  "status_code": 401,
  "duration_ms": 4.0,
  "client_ip": "127.0.0.1",
  "user_id": null
}
2025-08-07 14:52:23 | error | WARNING | Error response: {
  "method": "GET",
  "url": "http://localhost:8000/api/v1/auth/me",
  "status_code": 401,
  "duration_ms": 7.9,
  "client_ip": "127.0.0.1",
  "user_id": null
}
2025-08-07 15:41:08 | error | WARNING | Error response: {
  "method": "GET",
  "url": "http://localhost:8000/api/v1/auth/me",
  "status_code": 401,
  "duration_ms": 4.02,
  "client_ip": "127.0.0.1",
  "user_id": null
}
2025-08-07 16:15:28 | error | WARNING | Error response: {
  "method": "GET",
  "url": "http://localhost:8000/api/v1/auth/me",
  "status_code": 401,
  "duration_ms": 7.0,
  "client_ip": "127.0.0.1",
  "user_id": null
}
2025-08-07 16:16:07 | error | ERROR | System Error: {
  "event_type": "SYSTEM_ERROR",
  "timestamp": "2025-08-07T10:46:07.377352",
  "error_type": "ModuleNotFoundError",
  "error_message": "No module named 'app.models.vendor_compliance'",
  "context": "Request: GET /api/v1/vendors/12",
  "user_id": null,
  "stack_trace": "Traceback (most recent call last):\n  File \"D:\\Vendor Management System\\backend\\venv\\lib\\site-packages\\anyio\\streams\\memory.py\", line 98, in receive\n    return self.receive_nowait()\n  File \"D:\\Vendor Management System\\backend\\venv\\lib\\site-packages\\anyio\\streams\\memory.py\", line 93, in receive_nowait\n    raise WouldBlock\nanyio.WouldBlock\n\nDuring handling of the above exception, another exception occurred:\n\nTraceback (most recent call last):\n  File \"D:\\Vendor Management System\\backend\\venv\\lib\\site-packages\\starlette\\middleware\\base.py\", line 78, in call_next\n    message = await recv_stream.receive()\n  File \"D:\\Vendor Management System\\backend\\venv\\lib\\site-packages\\anyio\\streams\\memory.py\", line 118, in receive\n    raise EndOfStream\nanyio.EndOfStream\n\nDuring handling of the above exception, another exception occurred:\n\nTraceback (most recent call last):\n  File \"D:\\Vendor Management System\\backend\\app\\middleware\\logging_middleware.py\", line 29, in dispatch\n    response = await call_next(request)\n  File \"D:\\Vendor Management System\\backend\\venv\\lib\\site-packages\\starlette\\middleware\\base.py\", line 84, in call_next\n    raise app_exc\n  File \"D:\\Vendor Management System\\backend\\venv\\lib\\site-packages\\starlette\\middleware\\base.py\", line 70, in coro\n    await self.app(scope, receive_or_disconnect, send_no_error)\n  File \"D:\\Vendor Management System\\backend\\venv\\lib\\site-packages\\starlette\\middleware\\trustedhost.py\", line 51, in __call__\n    await self.app(scope, receive, send)\n  File \"D:\\Vendor Management System\\backend\\venv\\lib\\site-packages\\starlette\\middleware\\cors.py\", line 91, in __call__\n    await self.simple_response(scope, receive, send, request_headers=headers)\n  File \"D:\\Vendor Management System\\backend\\venv\\lib\\site-packages\\starlette\\middleware\\cors.py\", line 146, in simple_response\n    await self.app(scope, receive, send)\n  File \"D:\\Vendor Management System\\backend\\venv\\lib\\site-packages\\starlette\\middleware\\exceptions.py\", line 79, in __call__\n    raise exc\n  File \"D:\\Vendor Management System\\backend\\venv\\lib\\site-packages\\starlette\\middleware\\exceptions.py\", line 68, in __call__\n    await self.app(scope, receive, sender)\n  File \"D:\\Vendor Management System\\backend\\venv\\lib\\site-packages\\fastapi\\middleware\\asyncexitstack.py\", line 20, in __call__\n    raise e\n  File \"D:\\Vendor Management System\\backend\\venv\\lib\\site-packages\\fastapi\\middleware\\asyncexitstack.py\", line 17, in __call__\n    await self.app(scope, receive, send)\n  File \"D:\\Vendor Management System\\backend\\venv\\lib\\site-packages\\starlette\\routing.py\", line 718, in __call__\n    await route.handle(scope, receive, send)\n  File \"D:\\Vendor Management System\\backend\\venv\\lib\\site-packages\\starlette\\routing.py\", line 276, in handle\n    await self.app(scope, receive, send)\n  File \"D:\\Vendor Management System\\backend\\venv\\lib\\site-packages\\starlette\\routing.py\", line 66, in app\n    response = await func(request)\n  File \"D:\\Vendor Management System\\backend\\venv\\lib\\site-packages\\fastapi\\routing.py\", line 274, in app\n    raw_response = await run_endpoint_function(\n  File \"D:\\Vendor Management System\\backend\\venv\\lib\\site-packages\\fastapi\\routing.py\", line 191, in run_endpoint_function\n    return await dependant.call(**values)\n  File \"D:\\Vendor Management System\\backend\\app\\api\\vendors.py\", line 244, in get_vendor\n    from ..models.vendor_compliance import VendorCompliance\nModuleNotFoundError: No module named 'app.models.vendor_compliance'\n"
}
2025-08-07 16:16:07 | error | ERROR | Request Error: {
  "method": "GET",
  "url": "http://localhost:8000/api/v1/vendors/12",
  "error_type": "ModuleNotFoundError",
  "error_message": "No module named 'app.models.vendor_compliance'",
  "duration_ms": 7.5,
  "client_ip": "127.0.0.1",
  "user_id": null
}
2025-08-07 16:16:12 | error | ERROR | System Error: {
  "event_type": "SYSTEM_ERROR",
  "timestamp": "2025-08-07T10:46:12.798965",
  "error_type": "ModuleNotFoundError",
  "error_message": "No module named 'app.models.vendor_compliance'",
  "context": "Request: GET /api/v1/vendors/12",
  "user_id": null,
  "stack_trace": "Traceback (most recent call last):\n  File \"D:\\Vendor Management System\\backend\\venv\\lib\\site-packages\\anyio\\streams\\memory.py\", line 98, in receive\n    return self.receive_nowait()\n  File \"D:\\Vendor Management System\\backend\\venv\\lib\\site-packages\\anyio\\streams\\memory.py\", line 93, in receive_nowait\n    raise WouldBlock\nanyio.WouldBlock\n\nDuring handling of the above exception, another exception occurred:\n\nTraceback (most recent call last):\n  File \"D:\\Vendor Management System\\backend\\venv\\lib\\site-packages\\starlette\\middleware\\base.py\", line 78, in call_next\n    message = await recv_stream.receive()\n  File \"D:\\Vendor Management System\\backend\\venv\\lib\\site-packages\\anyio\\streams\\memory.py\", line 118, in receive\n    raise EndOfStream\nanyio.EndOfStream\n\nDuring handling of the above exception, another exception occurred:\n\nTraceback (most recent call last):\n  File \"D:\\Vendor Management System\\backend\\app\\middleware\\logging_middleware.py\", line 29, in dispatch\n    response = await call_next(request)\n  File \"D:\\Vendor Management System\\backend\\venv\\lib\\site-packages\\starlette\\middleware\\base.py\", line 84, in call_next\n    raise app_exc\n  File \"D:\\Vendor Management System\\backend\\venv\\lib\\site-packages\\starlette\\middleware\\base.py\", line 70, in coro\n    await self.app(scope, receive_or_disconnect, send_no_error)\n  File \"D:\\Vendor Management System\\backend\\venv\\lib\\site-packages\\starlette\\middleware\\trustedhost.py\", line 51, in __call__\n    await self.app(scope, receive, send)\n  File \"D:\\Vendor Management System\\backend\\venv\\lib\\site-packages\\starlette\\middleware\\cors.py\", line 91, in __call__\n    await self.simple_response(scope, receive, send, request_headers=headers)\n  File \"D:\\Vendor Management System\\backend\\venv\\lib\\site-packages\\starlette\\middleware\\cors.py\", line 146, in simple_response\n    await self.app(scope, receive, send)\n  File \"D:\\Vendor Management System\\backend\\venv\\lib\\site-packages\\starlette\\middleware\\exceptions.py\", line 79, in __call__\n    raise exc\n  File \"D:\\Vendor Management System\\backend\\venv\\lib\\site-packages\\starlette\\middleware\\exceptions.py\", line 68, in __call__\n    await self.app(scope, receive, sender)\n  File \"D:\\Vendor Management System\\backend\\venv\\lib\\site-packages\\fastapi\\middleware\\asyncexitstack.py\", line 20, in __call__\n    raise e\n  File \"D:\\Vendor Management System\\backend\\venv\\lib\\site-packages\\fastapi\\middleware\\asyncexitstack.py\", line 17, in __call__\n    await self.app(scope, receive, send)\n  File \"D:\\Vendor Management System\\backend\\venv\\lib\\site-packages\\starlette\\routing.py\", line 718, in __call__\n    await route.handle(scope, receive, send)\n  File \"D:\\Vendor Management System\\backend\\venv\\lib\\site-packages\\starlette\\routing.py\", line 276, in handle\n    await self.app(scope, receive, send)\n  File \"D:\\Vendor Management System\\backend\\venv\\lib\\site-packages\\starlette\\routing.py\", line 66, in app\n    response = await func(request)\n  File \"D:\\Vendor Management System\\backend\\venv\\lib\\site-packages\\fastapi\\routing.py\", line 274, in app\n    raw_response = await run_endpoint_function(\n  File \"D:\\Vendor Management System\\backend\\venv\\lib\\site-packages\\fastapi\\routing.py\", line 191, in run_endpoint_function\n    return await dependant.call(**values)\n  File \"D:\\Vendor Management System\\backend\\app\\api\\vendors.py\", line 244, in get_vendor\n    from ..models.vendor_compliance import VendorCompliance\nModuleNotFoundError: No module named 'app.models.vendor_compliance'\n"
}
2025-08-07 16:16:12 | error | ERROR | Request Error: {
  "method": "GET",
  "url": "http://localhost:8000/api/v1/vendors/12",
  "error_type": "ModuleNotFoundError",
  "error_message": "No module named 'app.models.vendor_compliance'",
  "duration_ms": 11.83,
  "client_ip": "127.0.0.1",
  "user_id": null
}
2025-08-07 16:16:13 | error | ERROR | System Error: {
  "event_type": "SYSTEM_ERROR",
  "timestamp": "2025-08-07T10:46:13.911262",
  "error_type": "ModuleNotFoundError",
  "error_message": "No module named 'app.models.vendor_compliance'",
  "context": "Request: GET /api/v1/vendors/12",
  "user_id": null,
  "stack_trace": "Traceback (most recent call last):\n  File \"D:\\Vendor Management System\\backend\\venv\\lib\\site-packages\\anyio\\streams\\memory.py\", line 98, in receive\n    return self.receive_nowait()\n  File \"D:\\Vendor Management System\\backend\\venv\\lib\\site-packages\\anyio\\streams\\memory.py\", line 93, in receive_nowait\n    raise WouldBlock\nanyio.WouldBlock\n\nDuring handling of the above exception, another exception occurred:\n\nTraceback (most recent call last):\n  File \"D:\\Vendor Management System\\backend\\venv\\lib\\site-packages\\starlette\\middleware\\base.py\", line 78, in call_next\n    message = await recv_stream.receive()\n  File \"D:\\Vendor Management System\\backend\\venv\\lib\\site-packages\\anyio\\streams\\memory.py\", line 118, in receive\n    raise EndOfStream\nanyio.EndOfStream\n\nDuring handling of the above exception, another exception occurred:\n\nTraceback (most recent call last):\n  File \"D:\\Vendor Management System\\backend\\app\\middleware\\logging_middleware.py\", line 29, in dispatch\n    response = await call_next(request)\n  File \"D:\\Vendor Management System\\backend\\venv\\lib\\site-packages\\starlette\\middleware\\base.py\", line 84, in call_next\n    raise app_exc\n  File \"D:\\Vendor Management System\\backend\\venv\\lib\\site-packages\\starlette\\middleware\\base.py\", line 70, in coro\n    await self.app(scope, receive_or_disconnect, send_no_error)\n  File \"D:\\Vendor Management System\\backend\\venv\\lib\\site-packages\\starlette\\middleware\\trustedhost.py\", line 51, in __call__\n    await self.app(scope, receive, send)\n  File \"D:\\Vendor Management System\\backend\\venv\\lib\\site-packages\\starlette\\middleware\\cors.py\", line 91, in __call__\n    await self.simple_response(scope, receive, send, request_headers=headers)\n  File \"D:\\Vendor Management System\\backend\\venv\\lib\\site-packages\\starlette\\middleware\\cors.py\", line 146, in simple_response\n    await self.app(scope, receive, send)\n  File \"D:\\Vendor Management System\\backend\\venv\\lib\\site-packages\\starlette\\middleware\\exceptions.py\", line 79, in __call__\n    raise exc\n  File \"D:\\Vendor Management System\\backend\\venv\\lib\\site-packages\\starlette\\middleware\\exceptions.py\", line 68, in __call__\n    await self.app(scope, receive, sender)\n  File \"D:\\Vendor Management System\\backend\\venv\\lib\\site-packages\\fastapi\\middleware\\asyncexitstack.py\", line 20, in __call__\n    raise e\n  File \"D:\\Vendor Management System\\backend\\venv\\lib\\site-packages\\fastapi\\middleware\\asyncexitstack.py\", line 17, in __call__\n    await self.app(scope, receive, send)\n  File \"D:\\Vendor Management System\\backend\\venv\\lib\\site-packages\\starlette\\routing.py\", line 718, in __call__\n    await route.handle(scope, receive, send)\n  File \"D:\\Vendor Management System\\backend\\venv\\lib\\site-packages\\starlette\\routing.py\", line 276, in handle\n    await self.app(scope, receive, send)\n  File \"D:\\Vendor Management System\\backend\\venv\\lib\\site-packages\\starlette\\routing.py\", line 66, in app\n    response = await func(request)\n  File \"D:\\Vendor Management System\\backend\\venv\\lib\\site-packages\\fastapi\\routing.py\", line 274, in app\n    raw_response = await run_endpoint_function(\n  File \"D:\\Vendor Management System\\backend\\venv\\lib\\site-packages\\fastapi\\routing.py\", line 191, in run_endpoint_function\n    return await dependant.call(**values)\n  File \"D:\\Vendor Management System\\backend\\app\\api\\vendors.py\", line 244, in get_vendor\n    from ..models.vendor_compliance import VendorCompliance\nModuleNotFoundError: No module named 'app.models.vendor_compliance'\n"
}
2025-08-07 16:16:13 | error | ERROR | Request Error: {
  "method": "GET",
  "url": "http://localhost:8000/api/v1/vendors/12",
  "error_type": "ModuleNotFoundError",
  "error_message": "No module named 'app.models.vendor_compliance'",
  "duration_ms": 10.34,
  "client_ip": "127.0.0.1",
  "user_id": null
}
2025-08-07 16:17:50 | error | ERROR | System Error: {
  "event_type": "SYSTEM_ERROR",
  "timestamp": "2025-08-07T10:47:50.223329",
  "error_type": "ModuleNotFoundError",
  "error_message": "No module named 'app.models.vendor_compliance'",
  "context": "Request: GET /api/v1/vendors/12",
  "user_id": null,
  "stack_trace": "Traceback (most recent call last):\n  File \"D:\\Vendor Management System\\backend\\venv\\lib\\site-packages\\anyio\\streams\\memory.py\", line 98, in receive\n    return self.receive_nowait()\n  File \"D:\\Vendor Management System\\backend\\venv\\lib\\site-packages\\anyio\\streams\\memory.py\", line 93, in receive_nowait\n    raise WouldBlock\nanyio.WouldBlock\n\nDuring handling of the above exception, another exception occurred:\n\nTraceback (most recent call last):\n  File \"D:\\Vendor Management System\\backend\\venv\\lib\\site-packages\\starlette\\middleware\\base.py\", line 78, in call_next\n    message = await recv_stream.receive()\n  File \"D:\\Vendor Management System\\backend\\venv\\lib\\site-packages\\anyio\\streams\\memory.py\", line 118, in receive\n    raise EndOfStream\nanyio.EndOfStream\n\nDuring handling of the above exception, another exception occurred:\n\nTraceback (most recent call last):\n  File \"D:\\Vendor Management System\\backend\\app\\middleware\\logging_middleware.py\", line 29, in dispatch\n    response = await call_next(request)\n  File \"D:\\Vendor Management System\\backend\\venv\\lib\\site-packages\\starlette\\middleware\\base.py\", line 84, in call_next\n    raise app_exc\n  File \"D:\\Vendor Management System\\backend\\venv\\lib\\site-packages\\starlette\\middleware\\base.py\", line 70, in coro\n    await self.app(scope, receive_or_disconnect, send_no_error)\n  File \"D:\\Vendor Management System\\backend\\venv\\lib\\site-packages\\starlette\\middleware\\trustedhost.py\", line 51, in __call__\n    await self.app(scope, receive, send)\n  File \"D:\\Vendor Management System\\backend\\venv\\lib\\site-packages\\starlette\\middleware\\cors.py\", line 91, in __call__\n    await self.simple_response(scope, receive, send, request_headers=headers)\n  File \"D:\\Vendor Management System\\backend\\venv\\lib\\site-packages\\starlette\\middleware\\cors.py\", line 146, in simple_response\n    await self.app(scope, receive, send)\n  File \"D:\\Vendor Management System\\backend\\venv\\lib\\site-packages\\starlette\\middleware\\exceptions.py\", line 79, in __call__\n    raise exc\n  File \"D:\\Vendor Management System\\backend\\venv\\lib\\site-packages\\starlette\\middleware\\exceptions.py\", line 68, in __call__\n    await self.app(scope, receive, sender)\n  File \"D:\\Vendor Management System\\backend\\venv\\lib\\site-packages\\fastapi\\middleware\\asyncexitstack.py\", line 20, in __call__\n    raise e\n  File \"D:\\Vendor Management System\\backend\\venv\\lib\\site-packages\\fastapi\\middleware\\asyncexitstack.py\", line 17, in __call__\n    await self.app(scope, receive, send)\n  File \"D:\\Vendor Management System\\backend\\venv\\lib\\site-packages\\starlette\\routing.py\", line 718, in __call__\n    await route.handle(scope, receive, send)\n  File \"D:\\Vendor Management System\\backend\\venv\\lib\\site-packages\\starlette\\routing.py\", line 276, in handle\n    await self.app(scope, receive, send)\n  File \"D:\\Vendor Management System\\backend\\venv\\lib\\site-packages\\starlette\\routing.py\", line 66, in app\n    response = await func(request)\n  File \"D:\\Vendor Management System\\backend\\venv\\lib\\site-packages\\fastapi\\routing.py\", line 274, in app\n    raw_response = await run_endpoint_function(\n  File \"D:\\Vendor Management System\\backend\\venv\\lib\\site-packages\\fastapi\\routing.py\", line 191, in run_endpoint_function\n    return await dependant.call(**values)\n  File \"D:\\Vendor Management System\\backend\\app\\api\\vendors.py\", line 244, in get_vendor\n    from ..models.vendor_compliance import VendorCompliance\nModuleNotFoundError: No module named 'app.models.vendor_compliance'\n"
}
2025-08-07 16:17:50 | error | ERROR | Request Error: {
  "method": "GET",
  "url": "http://localhost:8000/api/v1/vendors/12",
  "error_type": "ModuleNotFoundError",
  "error_message": "No module named 'app.models.vendor_compliance'",
  "duration_ms": 7.79,
  "client_ip": "127.0.0.1",
  "user_id": null
}
2025-08-07 16:17:52 | error | ERROR | System Error: {
  "event_type": "SYSTEM_ERROR",
  "timestamp": "2025-08-07T10:47:52.585124",
  "error_type": "ModuleNotFoundError",
  "error_message": "No module named 'app.models.vendor_compliance'",
  "context": "Request: GET /api/v1/vendors/12",
  "user_id": null,
  "stack_trace": "Traceback (most recent call last):\n  File \"D:\\Vendor Management System\\backend\\venv\\lib\\site-packages\\anyio\\streams\\memory.py\", line 98, in receive\n    return self.receive_nowait()\n  File \"D:\\Vendor Management System\\backend\\venv\\lib\\site-packages\\anyio\\streams\\memory.py\", line 93, in receive_nowait\n    raise WouldBlock\nanyio.WouldBlock\n\nDuring handling of the above exception, another exception occurred:\n\nTraceback (most recent call last):\n  File \"D:\\Vendor Management System\\backend\\venv\\lib\\site-packages\\starlette\\middleware\\base.py\", line 78, in call_next\n    message = await recv_stream.receive()\n  File \"D:\\Vendor Management System\\backend\\venv\\lib\\site-packages\\anyio\\streams\\memory.py\", line 118, in receive\n    raise EndOfStream\nanyio.EndOfStream\n\nDuring handling of the above exception, another exception occurred:\n\nTraceback (most recent call last):\n  File \"D:\\Vendor Management System\\backend\\app\\middleware\\logging_middleware.py\", line 29, in dispatch\n    response = await call_next(request)\n  File \"D:\\Vendor Management System\\backend\\venv\\lib\\site-packages\\starlette\\middleware\\base.py\", line 84, in call_next\n    raise app_exc\n  File \"D:\\Vendor Management System\\backend\\venv\\lib\\site-packages\\starlette\\middleware\\base.py\", line 70, in coro\n    await self.app(scope, receive_or_disconnect, send_no_error)\n  File \"D:\\Vendor Management System\\backend\\venv\\lib\\site-packages\\starlette\\middleware\\trustedhost.py\", line 51, in __call__\n    await self.app(scope, receive, send)\n  File \"D:\\Vendor Management System\\backend\\venv\\lib\\site-packages\\starlette\\middleware\\cors.py\", line 91, in __call__\n    await self.simple_response(scope, receive, send, request_headers=headers)\n  File \"D:\\Vendor Management System\\backend\\venv\\lib\\site-packages\\starlette\\middleware\\cors.py\", line 146, in simple_response\n    await self.app(scope, receive, send)\n  File \"D:\\Vendor Management System\\backend\\venv\\lib\\site-packages\\starlette\\middleware\\exceptions.py\", line 79, in __call__\n    raise exc\n  File \"D:\\Vendor Management System\\backend\\venv\\lib\\site-packages\\starlette\\middleware\\exceptions.py\", line 68, in __call__\n    await self.app(scope, receive, sender)\n  File \"D:\\Vendor Management System\\backend\\venv\\lib\\site-packages\\fastapi\\middleware\\asyncexitstack.py\", line 20, in __call__\n    raise e\n  File \"D:\\Vendor Management System\\backend\\venv\\lib\\site-packages\\fastapi\\middleware\\asyncexitstack.py\", line 17, in __call__\n    await self.app(scope, receive, send)\n  File \"D:\\Vendor Management System\\backend\\venv\\lib\\site-packages\\starlette\\routing.py\", line 718, in __call__\n    await route.handle(scope, receive, send)\n  File \"D:\\Vendor Management System\\backend\\venv\\lib\\site-packages\\starlette\\routing.py\", line 276, in handle\n    await self.app(scope, receive, send)\n  File \"D:\\Vendor Management System\\backend\\venv\\lib\\site-packages\\starlette\\routing.py\", line 66, in app\n    response = await func(request)\n  File \"D:\\Vendor Management System\\backend\\venv\\lib\\site-packages\\fastapi\\routing.py\", line 274, in app\n    raw_response = await run_endpoint_function(\n  File \"D:\\Vendor Management System\\backend\\venv\\lib\\site-packages\\fastapi\\routing.py\", line 191, in run_endpoint_function\n    return await dependant.call(**values)\n  File \"D:\\Vendor Management System\\backend\\app\\api\\vendors.py\", line 244, in get_vendor\n    from ..models.vendor_compliance import VendorCompliance\nModuleNotFoundError: No module named 'app.models.vendor_compliance'\n"
}
2025-08-07 16:17:52 | error | ERROR | Request Error: {
  "method": "GET",
  "url": "http://localhost:8000/api/v1/vendors/12",
  "error_type": "ModuleNotFoundError",
  "error_message": "No module named 'app.models.vendor_compliance'",
  "duration_ms": 10.5,
  "client_ip": "127.0.0.1",
  "user_id": null
}
2025-08-07 16:19:03 | error | ERROR | System Error: {
  "event_type": "SYSTEM_ERROR",
  "timestamp": "2025-08-07T10:49:03.855127",
  "error_type": "ModuleNotFoundError",
  "error_message": "No module named 'app.models.vendor_compliance'",
  "context": "Request: GET /api/v1/vendors/12",
  "user_id": null,
  "stack_trace": "Traceback (most recent call last):\n  File \"D:\\Vendor Management System\\backend\\venv\\lib\\site-packages\\anyio\\streams\\memory.py\", line 98, in receive\n    return self.receive_nowait()\n  File \"D:\\Vendor Management System\\backend\\venv\\lib\\site-packages\\anyio\\streams\\memory.py\", line 93, in receive_nowait\n    raise WouldBlock\nanyio.WouldBlock\n\nDuring handling of the above exception, another exception occurred:\n\nTraceback (most recent call last):\n  File \"D:\\Vendor Management System\\backend\\venv\\lib\\site-packages\\starlette\\middleware\\base.py\", line 78, in call_next\n    message = await recv_stream.receive()\n  File \"D:\\Vendor Management System\\backend\\venv\\lib\\site-packages\\anyio\\streams\\memory.py\", line 118, in receive\n    raise EndOfStream\nanyio.EndOfStream\n\nDuring handling of the above exception, another exception occurred:\n\nTraceback (most recent call last):\n  File \"D:\\Vendor Management System\\backend\\app\\middleware\\logging_middleware.py\", line 29, in dispatch\n    response = await call_next(request)\n  File \"D:\\Vendor Management System\\backend\\venv\\lib\\site-packages\\starlette\\middleware\\base.py\", line 84, in call_next\n    raise app_exc\n  File \"D:\\Vendor Management System\\backend\\venv\\lib\\site-packages\\starlette\\middleware\\base.py\", line 70, in coro\n    await self.app(scope, receive_or_disconnect, send_no_error)\n  File \"D:\\Vendor Management System\\backend\\venv\\lib\\site-packages\\starlette\\middleware\\trustedhost.py\", line 51, in __call__\n    await self.app(scope, receive, send)\n  File \"D:\\Vendor Management System\\backend\\venv\\lib\\site-packages\\starlette\\middleware\\cors.py\", line 91, in __call__\n    await self.simple_response(scope, receive, send, request_headers=headers)\n  File \"D:\\Vendor Management System\\backend\\venv\\lib\\site-packages\\starlette\\middleware\\cors.py\", line 146, in simple_response\n    await self.app(scope, receive, send)\n  File \"D:\\Vendor Management System\\backend\\venv\\lib\\site-packages\\starlette\\middleware\\exceptions.py\", line 79, in __call__\n    raise exc\n  File \"D:\\Vendor Management System\\backend\\venv\\lib\\site-packages\\starlette\\middleware\\exceptions.py\", line 68, in __call__\n    await self.app(scope, receive, sender)\n  File \"D:\\Vendor Management System\\backend\\venv\\lib\\site-packages\\fastapi\\middleware\\asyncexitstack.py\", line 20, in __call__\n    raise e\n  File \"D:\\Vendor Management System\\backend\\venv\\lib\\site-packages\\fastapi\\middleware\\asyncexitstack.py\", line 17, in __call__\n    await self.app(scope, receive, send)\n  File \"D:\\Vendor Management System\\backend\\venv\\lib\\site-packages\\starlette\\routing.py\", line 718, in __call__\n    await route.handle(scope, receive, send)\n  File \"D:\\Vendor Management System\\backend\\venv\\lib\\site-packages\\starlette\\routing.py\", line 276, in handle\n    await self.app(scope, receive, send)\n  File \"D:\\Vendor Management System\\backend\\venv\\lib\\site-packages\\starlette\\routing.py\", line 66, in app\n    response = await func(request)\n  File \"D:\\Vendor Management System\\backend\\venv\\lib\\site-packages\\fastapi\\routing.py\", line 274, in app\n    raw_response = await run_endpoint_function(\n  File \"D:\\Vendor Management System\\backend\\venv\\lib\\site-packages\\fastapi\\routing.py\", line 191, in run_endpoint_function\n    return await dependant.call(**values)\n  File \"D:\\Vendor Management System\\backend\\app\\api\\vendors.py\", line 244, in get_vendor\n    from ..models.vendor_compliance import VendorCompliance\nModuleNotFoundError: No module named 'app.models.vendor_compliance'\n"
}
2025-08-07 16:19:03 | error | ERROR | Request Error: {
  "method": "GET",
  "url": "http://localhost:8000/api/v1/vendors/12",
  "error_type": "ModuleNotFoundError",
  "error_message": "No module named 'app.models.vendor_compliance'",
  "duration_ms": 9.28,
  "client_ip": "127.0.0.1",
  "user_id": null
}
2025-08-07 16:19:05 | error | ERROR | System Error: {
  "event_type": "SYSTEM_ERROR",
  "timestamp": "2025-08-07T10:49:05.022690",
  "error_type": "ModuleNotFoundError",
  "error_message": "No module named 'app.models.vendor_compliance'",
  "context": "Request: GET /api/v1/vendors/12",
  "user_id": null,
  "stack_trace": "Traceback (most recent call last):\n  File \"D:\\Vendor Management System\\backend\\venv\\lib\\site-packages\\anyio\\streams\\memory.py\", line 98, in receive\n    return self.receive_nowait()\n  File \"D:\\Vendor Management System\\backend\\venv\\lib\\site-packages\\anyio\\streams\\memory.py\", line 93, in receive_nowait\n    raise WouldBlock\nanyio.WouldBlock\n\nDuring handling of the above exception, another exception occurred:\n\nTraceback (most recent call last):\n  File \"D:\\Vendor Management System\\backend\\venv\\lib\\site-packages\\starlette\\middleware\\base.py\", line 78, in call_next\n    message = await recv_stream.receive()\n  File \"D:\\Vendor Management System\\backend\\venv\\lib\\site-packages\\anyio\\streams\\memory.py\", line 118, in receive\n    raise EndOfStream\nanyio.EndOfStream\n\nDuring handling of the above exception, another exception occurred:\n\nTraceback (most recent call last):\n  File \"D:\\Vendor Management System\\backend\\app\\middleware\\logging_middleware.py\", line 29, in dispatch\n    response = await call_next(request)\n  File \"D:\\Vendor Management System\\backend\\venv\\lib\\site-packages\\starlette\\middleware\\base.py\", line 84, in call_next\n    raise app_exc\n  File \"D:\\Vendor Management System\\backend\\venv\\lib\\site-packages\\starlette\\middleware\\base.py\", line 70, in coro\n    await self.app(scope, receive_or_disconnect, send_no_error)\n  File \"D:\\Vendor Management System\\backend\\venv\\lib\\site-packages\\starlette\\middleware\\trustedhost.py\", line 51, in __call__\n    await self.app(scope, receive, send)\n  File \"D:\\Vendor Management System\\backend\\venv\\lib\\site-packages\\starlette\\middleware\\cors.py\", line 91, in __call__\n    await self.simple_response(scope, receive, send, request_headers=headers)\n  File \"D:\\Vendor Management System\\backend\\venv\\lib\\site-packages\\starlette\\middleware\\cors.py\", line 146, in simple_response\n    await self.app(scope, receive, send)\n  File \"D:\\Vendor Management System\\backend\\venv\\lib\\site-packages\\starlette\\middleware\\exceptions.py\", line 79, in __call__\n    raise exc\n  File \"D:\\Vendor Management System\\backend\\venv\\lib\\site-packages\\starlette\\middleware\\exceptions.py\", line 68, in __call__\n    await self.app(scope, receive, sender)\n  File \"D:\\Vendor Management System\\backend\\venv\\lib\\site-packages\\fastapi\\middleware\\asyncexitstack.py\", line 20, in __call__\n    raise e\n  File \"D:\\Vendor Management System\\backend\\venv\\lib\\site-packages\\fastapi\\middleware\\asyncexitstack.py\", line 17, in __call__\n    await self.app(scope, receive, send)\n  File \"D:\\Vendor Management System\\backend\\venv\\lib\\site-packages\\starlette\\routing.py\", line 718, in __call__\n    await route.handle(scope, receive, send)\n  File \"D:\\Vendor Management System\\backend\\venv\\lib\\site-packages\\starlette\\routing.py\", line 276, in handle\n    await self.app(scope, receive, send)\n  File \"D:\\Vendor Management System\\backend\\venv\\lib\\site-packages\\starlette\\routing.py\", line 66, in app\n    response = await func(request)\n  File \"D:\\Vendor Management System\\backend\\venv\\lib\\site-packages\\fastapi\\routing.py\", line 274, in app\n    raw_response = await run_endpoint_function(\n  File \"D:\\Vendor Management System\\backend\\venv\\lib\\site-packages\\fastapi\\routing.py\", line 191, in run_endpoint_function\n    return await dependant.call(**values)\n  File \"D:\\Vendor Management System\\backend\\app\\api\\vendors.py\", line 244, in get_vendor\n    from ..models.vendor_compliance import VendorCompliance\nModuleNotFoundError: No module named 'app.models.vendor_compliance'\n"
}
2025-08-07 16:19:05 | error | ERROR | Request Error: {
  "method": "GET",
  "url": "http://localhost:8000/api/v1/vendors/12",
  "error_type": "ModuleNotFoundError",
  "error_message": "No module named 'app.models.vendor_compliance'",
  "duration_ms": 12.89,
  "client_ip": "127.0.0.1",
  "user_id": null
}
2025-08-07 16:20:30 | error | ERROR | System Error: {
  "event_type": "SYSTEM_ERROR",
  "timestamp": "2025-08-07T10:50:30.871255",
  "error_type": "ModuleNotFoundError",
  "error_message": "No module named 'app.models.vendor_compliance'",
  "context": "Request: GET /api/v1/vendors/12",
  "user_id": null,
  "stack_trace": "Traceback (most recent call last):\n  File \"D:\\Vendor Management System\\backend\\venv\\lib\\site-packages\\anyio\\streams\\memory.py\", line 98, in receive\n    return self.receive_nowait()\n  File \"D:\\Vendor Management System\\backend\\venv\\lib\\site-packages\\anyio\\streams\\memory.py\", line 93, in receive_nowait\n    raise WouldBlock\nanyio.WouldBlock\n\nDuring handling of the above exception, another exception occurred:\n\nTraceback (most recent call last):\n  File \"D:\\Vendor Management System\\backend\\venv\\lib\\site-packages\\starlette\\middleware\\base.py\", line 78, in call_next\n    message = await recv_stream.receive()\n  File \"D:\\Vendor Management System\\backend\\venv\\lib\\site-packages\\anyio\\streams\\memory.py\", line 118, in receive\n    raise EndOfStream\nanyio.EndOfStream\n\nDuring handling of the above exception, another exception occurred:\n\nTraceback (most recent call last):\n  File \"D:\\Vendor Management System\\backend\\app\\middleware\\logging_middleware.py\", line 29, in dispatch\n    response = await call_next(request)\n  File \"D:\\Vendor Management System\\backend\\venv\\lib\\site-packages\\starlette\\middleware\\base.py\", line 84, in call_next\n    raise app_exc\n  File \"D:\\Vendor Management System\\backend\\venv\\lib\\site-packages\\starlette\\middleware\\base.py\", line 70, in coro\n    await self.app(scope, receive_or_disconnect, send_no_error)\n  File \"D:\\Vendor Management System\\backend\\venv\\lib\\site-packages\\starlette\\middleware\\trustedhost.py\", line 51, in __call__\n    await self.app(scope, receive, send)\n  File \"D:\\Vendor Management System\\backend\\venv\\lib\\site-packages\\starlette\\middleware\\cors.py\", line 91, in __call__\n    await self.simple_response(scope, receive, send, request_headers=headers)\n  File \"D:\\Vendor Management System\\backend\\venv\\lib\\site-packages\\starlette\\middleware\\cors.py\", line 146, in simple_response\n    await self.app(scope, receive, send)\n  File \"D:\\Vendor Management System\\backend\\venv\\lib\\site-packages\\starlette\\middleware\\exceptions.py\", line 79, in __call__\n    raise exc\n  File \"D:\\Vendor Management System\\backend\\venv\\lib\\site-packages\\starlette\\middleware\\exceptions.py\", line 68, in __call__\n    await self.app(scope, receive, sender)\n  File \"D:\\Vendor Management System\\backend\\venv\\lib\\site-packages\\fastapi\\middleware\\asyncexitstack.py\", line 20, in __call__\n    raise e\n  File \"D:\\Vendor Management System\\backend\\venv\\lib\\site-packages\\fastapi\\middleware\\asyncexitstack.py\", line 17, in __call__\n    await self.app(scope, receive, send)\n  File \"D:\\Vendor Management System\\backend\\venv\\lib\\site-packages\\starlette\\routing.py\", line 718, in __call__\n    await route.handle(scope, receive, send)\n  File \"D:\\Vendor Management System\\backend\\venv\\lib\\site-packages\\starlette\\routing.py\", line 276, in handle\n    await self.app(scope, receive, send)\n  File \"D:\\Vendor Management System\\backend\\venv\\lib\\site-packages\\starlette\\routing.py\", line 66, in app\n    response = await func(request)\n  File \"D:\\Vendor Management System\\backend\\venv\\lib\\site-packages\\fastapi\\routing.py\", line 274, in app\n    raw_response = await run_endpoint_function(\n  File \"D:\\Vendor Management System\\backend\\venv\\lib\\site-packages\\fastapi\\routing.py\", line 191, in run_endpoint_function\n    return await dependant.call(**values)\n  File \"D:\\Vendor Management System\\backend\\app\\api\\vendors.py\", line 244, in get_vendor\n    from ..models.vendor_compliance import VendorCompliance\nModuleNotFoundError: No module named 'app.models.vendor_compliance'\n"
}
2025-08-07 16:20:30 | error | ERROR | Request Error: {
  "method": "GET",
  "url": "http://localhost:8000/api/v1/vendors/12",
  "error_type": "ModuleNotFoundError",
  "error_message": "No module named 'app.models.vendor_compliance'",
  "duration_ms": 9.73,
  "client_ip": "127.0.0.1",
  "user_id": null
}
2025-08-07 16:20:32 | error | ERROR | System Error: {
  "event_type": "SYSTEM_ERROR",
  "timestamp": "2025-08-07T10:50:32.962953",
  "error_type": "ModuleNotFoundError",
  "error_message": "No module named 'app.models.vendor_compliance'",
  "context": "Request: GET /api/v1/vendors/12",
  "user_id": null,
  "stack_trace": "Traceback (most recent call last):\n  File \"D:\\Vendor Management System\\backend\\venv\\lib\\site-packages\\anyio\\streams\\memory.py\", line 98, in receive\n    return self.receive_nowait()\n  File \"D:\\Vendor Management System\\backend\\venv\\lib\\site-packages\\anyio\\streams\\memory.py\", line 93, in receive_nowait\n    raise WouldBlock\nanyio.WouldBlock\n\nDuring handling of the above exception, another exception occurred:\n\nTraceback (most recent call last):\n  File \"D:\\Vendor Management System\\backend\\venv\\lib\\site-packages\\starlette\\middleware\\base.py\", line 78, in call_next\n    message = await recv_stream.receive()\n  File \"D:\\Vendor Management System\\backend\\venv\\lib\\site-packages\\anyio\\streams\\memory.py\", line 118, in receive\n    raise EndOfStream\nanyio.EndOfStream\n\nDuring handling of the above exception, another exception occurred:\n\nTraceback (most recent call last):\n  File \"D:\\Vendor Management System\\backend\\app\\middleware\\logging_middleware.py\", line 29, in dispatch\n    response = await call_next(request)\n  File \"D:\\Vendor Management System\\backend\\venv\\lib\\site-packages\\starlette\\middleware\\base.py\", line 84, in call_next\n    raise app_exc\n  File \"D:\\Vendor Management System\\backend\\venv\\lib\\site-packages\\starlette\\middleware\\base.py\", line 70, in coro\n    await self.app(scope, receive_or_disconnect, send_no_error)\n  File \"D:\\Vendor Management System\\backend\\venv\\lib\\site-packages\\starlette\\middleware\\trustedhost.py\", line 51, in __call__\n    await self.app(scope, receive, send)\n  File \"D:\\Vendor Management System\\backend\\venv\\lib\\site-packages\\starlette\\middleware\\cors.py\", line 91, in __call__\n    await self.simple_response(scope, receive, send, request_headers=headers)\n  File \"D:\\Vendor Management System\\backend\\venv\\lib\\site-packages\\starlette\\middleware\\cors.py\", line 146, in simple_response\n    await self.app(scope, receive, send)\n  File \"D:\\Vendor Management System\\backend\\venv\\lib\\site-packages\\starlette\\middleware\\exceptions.py\", line 79, in __call__\n    raise exc\n  File \"D:\\Vendor Management System\\backend\\venv\\lib\\site-packages\\starlette\\middleware\\exceptions.py\", line 68, in __call__\n    await self.app(scope, receive, sender)\n  File \"D:\\Vendor Management System\\backend\\venv\\lib\\site-packages\\fastapi\\middleware\\asyncexitstack.py\", line 20, in __call__\n    raise e\n  File \"D:\\Vendor Management System\\backend\\venv\\lib\\site-packages\\fastapi\\middleware\\asyncexitstack.py\", line 17, in __call__\n    await self.app(scope, receive, send)\n  File \"D:\\Vendor Management System\\backend\\venv\\lib\\site-packages\\starlette\\routing.py\", line 718, in __call__\n    await route.handle(scope, receive, send)\n  File \"D:\\Vendor Management System\\backend\\venv\\lib\\site-packages\\starlette\\routing.py\", line 276, in handle\n    await self.app(scope, receive, send)\n  File \"D:\\Vendor Management System\\backend\\venv\\lib\\site-packages\\starlette\\routing.py\", line 66, in app\n    response = await func(request)\n  File \"D:\\Vendor Management System\\backend\\venv\\lib\\site-packages\\fastapi\\routing.py\", line 274, in app\n    raw_response = await run_endpoint_function(\n  File \"D:\\Vendor Management System\\backend\\venv\\lib\\site-packages\\fastapi\\routing.py\", line 191, in run_endpoint_function\n    return await dependant.call(**values)\n  File \"D:\\Vendor Management System\\backend\\app\\api\\vendors.py\", line 244, in get_vendor\n    from ..models.vendor_compliance import VendorCompliance\nModuleNotFoundError: No module named 'app.models.vendor_compliance'\n"
}
2025-08-07 16:20:32 | error | ERROR | Request Error: {
  "method": "GET",
  "url": "http://localhost:8000/api/v1/vendors/12",
  "error_type": "ModuleNotFoundError",
  "error_message": "No module named 'app.models.vendor_compliance'",
  "duration_ms": 10.12,
  "client_ip": "127.0.0.1",
  "user_id": null
}
2025-08-07 16:22:18 | error | ERROR | System Error: {
  "event_type": "SYSTEM_ERROR",
  "timestamp": "2025-08-07T10:52:18.744522",
  "error_type": "ModuleNotFoundError",
  "error_message": "No module named 'app.models.vendor_compliance'",
  "context": "Request: GET /api/v1/vendors/12",
  "user_id": null,
  "stack_trace": "Traceback (most recent call last):\n  File \"D:\\Vendor Management System\\backend\\venv\\lib\\site-packages\\anyio\\streams\\memory.py\", line 98, in receive\n    return self.receive_nowait()\n  File \"D:\\Vendor Management System\\backend\\venv\\lib\\site-packages\\anyio\\streams\\memory.py\", line 93, in receive_nowait\n    raise WouldBlock\nanyio.WouldBlock\n\nDuring handling of the above exception, another exception occurred:\n\nTraceback (most recent call last):\n  File \"D:\\Vendor Management System\\backend\\venv\\lib\\site-packages\\starlette\\middleware\\base.py\", line 78, in call_next\n    message = await recv_stream.receive()\n  File \"D:\\Vendor Management System\\backend\\venv\\lib\\site-packages\\anyio\\streams\\memory.py\", line 118, in receive\n    raise EndOfStream\nanyio.EndOfStream\n\nDuring handling of the above exception, another exception occurred:\n\nTraceback (most recent call last):\n  File \"D:\\Vendor Management System\\backend\\app\\middleware\\logging_middleware.py\", line 29, in dispatch\n    response = await call_next(request)\n  File \"D:\\Vendor Management System\\backend\\venv\\lib\\site-packages\\starlette\\middleware\\base.py\", line 84, in call_next\n    raise app_exc\n  File \"D:\\Vendor Management System\\backend\\venv\\lib\\site-packages\\starlette\\middleware\\base.py\", line 70, in coro\n    await self.app(scope, receive_or_disconnect, send_no_error)\n  File \"D:\\Vendor Management System\\backend\\venv\\lib\\site-packages\\starlette\\middleware\\trustedhost.py\", line 51, in __call__\n    await self.app(scope, receive, send)\n  File \"D:\\Vendor Management System\\backend\\venv\\lib\\site-packages\\starlette\\middleware\\cors.py\", line 91, in __call__\n    await self.simple_response(scope, receive, send, request_headers=headers)\n  File \"D:\\Vendor Management System\\backend\\venv\\lib\\site-packages\\starlette\\middleware\\cors.py\", line 146, in simple_response\n    await self.app(scope, receive, send)\n  File \"D:\\Vendor Management System\\backend\\venv\\lib\\site-packages\\starlette\\middleware\\exceptions.py\", line 79, in __call__\n    raise exc\n  File \"D:\\Vendor Management System\\backend\\venv\\lib\\site-packages\\starlette\\middleware\\exceptions.py\", line 68, in __call__\n    await self.app(scope, receive, sender)\n  File \"D:\\Vendor Management System\\backend\\venv\\lib\\site-packages\\fastapi\\middleware\\asyncexitstack.py\", line 20, in __call__\n    raise e\n  File \"D:\\Vendor Management System\\backend\\venv\\lib\\site-packages\\fastapi\\middleware\\asyncexitstack.py\", line 17, in __call__\n    await self.app(scope, receive, send)\n  File \"D:\\Vendor Management System\\backend\\venv\\lib\\site-packages\\starlette\\routing.py\", line 718, in __call__\n    await route.handle(scope, receive, send)\n  File \"D:\\Vendor Management System\\backend\\venv\\lib\\site-packages\\starlette\\routing.py\", line 276, in handle\n    await self.app(scope, receive, send)\n  File \"D:\\Vendor Management System\\backend\\venv\\lib\\site-packages\\starlette\\routing.py\", line 66, in app\n    response = await func(request)\n  File \"D:\\Vendor Management System\\backend\\venv\\lib\\site-packages\\fastapi\\routing.py\", line 274, in app\n    raw_response = await run_endpoint_function(\n  File \"D:\\Vendor Management System\\backend\\venv\\lib\\site-packages\\fastapi\\routing.py\", line 191, in run_endpoint_function\n    return await dependant.call(**values)\n  File \"D:\\Vendor Management System\\backend\\app\\api\\vendors.py\", line 244, in get_vendor\n    from ..models.vendor_compliance import VendorCompliance\nModuleNotFoundError: No module named 'app.models.vendor_compliance'\n"
}
2025-08-07 16:22:18 | error | ERROR | Request Error: {
  "method": "GET",
  "url": "http://localhost:8000/api/v1/vendors/12",
  "error_type": "ModuleNotFoundError",
  "error_message": "No module named 'app.models.vendor_compliance'",
  "duration_ms": 88.62,
  "client_ip": "127.0.0.1",
  "user_id": null
}
2025-08-07 16:22:22 | error | ERROR | System Error: {
  "event_type": "SYSTEM_ERROR",
  "timestamp": "2025-08-07T10:52:22.697987",
  "error_type": "ModuleNotFoundError",
  "error_message": "No module named 'app.models.vendor_compliance'",
  "context": "Request: GET /api/v1/vendors/12",
  "user_id": null,
  "stack_trace": "Traceback (most recent call last):\n  File \"D:\\Vendor Management System\\backend\\venv\\lib\\site-packages\\anyio\\streams\\memory.py\", line 98, in receive\n    return self.receive_nowait()\n  File \"D:\\Vendor Management System\\backend\\venv\\lib\\site-packages\\anyio\\streams\\memory.py\", line 93, in receive_nowait\n    raise WouldBlock\nanyio.WouldBlock\n\nDuring handling of the above exception, another exception occurred:\n\nTraceback (most recent call last):\n  File \"D:\\Vendor Management System\\backend\\venv\\lib\\site-packages\\starlette\\middleware\\base.py\", line 78, in call_next\n    message = await recv_stream.receive()\n  File \"D:\\Vendor Management System\\backend\\venv\\lib\\site-packages\\anyio\\streams\\memory.py\", line 118, in receive\n    raise EndOfStream\nanyio.EndOfStream\n\nDuring handling of the above exception, another exception occurred:\n\nTraceback (most recent call last):\n  File \"D:\\Vendor Management System\\backend\\app\\middleware\\logging_middleware.py\", line 29, in dispatch\n    response = await call_next(request)\n  File \"D:\\Vendor Management System\\backend\\venv\\lib\\site-packages\\starlette\\middleware\\base.py\", line 84, in call_next\n    raise app_exc\n  File \"D:\\Vendor Management System\\backend\\venv\\lib\\site-packages\\starlette\\middleware\\base.py\", line 70, in coro\n    await self.app(scope, receive_or_disconnect, send_no_error)\n  File \"D:\\Vendor Management System\\backend\\venv\\lib\\site-packages\\starlette\\middleware\\trustedhost.py\", line 51, in __call__\n    await self.app(scope, receive, send)\n  File \"D:\\Vendor Management System\\backend\\venv\\lib\\site-packages\\starlette\\middleware\\cors.py\", line 91, in __call__\n    await self.simple_response(scope, receive, send, request_headers=headers)\n  File \"D:\\Vendor Management System\\backend\\venv\\lib\\site-packages\\starlette\\middleware\\cors.py\", line 146, in simple_response\n    await self.app(scope, receive, send)\n  File \"D:\\Vendor Management System\\backend\\venv\\lib\\site-packages\\starlette\\middleware\\exceptions.py\", line 79, in __call__\n    raise exc\n  File \"D:\\Vendor Management System\\backend\\venv\\lib\\site-packages\\starlette\\middleware\\exceptions.py\", line 68, in __call__\n    await self.app(scope, receive, sender)\n  File \"D:\\Vendor Management System\\backend\\venv\\lib\\site-packages\\fastapi\\middleware\\asyncexitstack.py\", line 20, in __call__\n    raise e\n  File \"D:\\Vendor Management System\\backend\\venv\\lib\\site-packages\\fastapi\\middleware\\asyncexitstack.py\", line 17, in __call__\n    await self.app(scope, receive, send)\n  File \"D:\\Vendor Management System\\backend\\venv\\lib\\site-packages\\starlette\\routing.py\", line 718, in __call__\n    await route.handle(scope, receive, send)\n  File \"D:\\Vendor Management System\\backend\\venv\\lib\\site-packages\\starlette\\routing.py\", line 276, in handle\n    await self.app(scope, receive, send)\n  File \"D:\\Vendor Management System\\backend\\venv\\lib\\site-packages\\starlette\\routing.py\", line 66, in app\n    response = await func(request)\n  File \"D:\\Vendor Management System\\backend\\venv\\lib\\site-packages\\fastapi\\routing.py\", line 274, in app\n    raw_response = await run_endpoint_function(\n  File \"D:\\Vendor Management System\\backend\\venv\\lib\\site-packages\\fastapi\\routing.py\", line 191, in run_endpoint_function\n    return await dependant.call(**values)\n  File \"D:\\Vendor Management System\\backend\\app\\api\\vendors.py\", line 244, in get_vendor\n    from ..models.vendor_compliance import VendorCompliance\nModuleNotFoundError: No module named 'app.models.vendor_compliance'\n"
}
2025-08-07 16:22:22 | error | ERROR | Request Error: {
  "method": "GET",
  "url": "http://localhost:8000/api/v1/vendors/12",
  "error_type": "ModuleNotFoundError",
  "error_message": "No module named 'app.models.vendor_compliance'",
  "duration_ms": 16.64,
  "client_ip": "127.0.0.1",
  "user_id": null
}
2025-08-07 16:22:30 | error | ERROR | System Error: {
  "event_type": "SYSTEM_ERROR",
  "timestamp": "2025-08-07T10:52:30.531180",
  "error_type": "ModuleNotFoundError",
  "error_message": "No module named 'app.models.vendor_compliance'",
  "context": "Request: GET /api/v1/vendors/12",
  "user_id": null,
  "stack_trace": "Traceback (most recent call last):\n  File \"D:\\Vendor Management System\\backend\\venv\\lib\\site-packages\\anyio\\streams\\memory.py\", line 98, in receive\n    return self.receive_nowait()\n  File \"D:\\Vendor Management System\\backend\\venv\\lib\\site-packages\\anyio\\streams\\memory.py\", line 93, in receive_nowait\n    raise WouldBlock\nanyio.WouldBlock\n\nDuring handling of the above exception, another exception occurred:\n\nTraceback (most recent call last):\n  File \"D:\\Vendor Management System\\backend\\venv\\lib\\site-packages\\starlette\\middleware\\base.py\", line 78, in call_next\n    message = await recv_stream.receive()\n  File \"D:\\Vendor Management System\\backend\\venv\\lib\\site-packages\\anyio\\streams\\memory.py\", line 118, in receive\n    raise EndOfStream\nanyio.EndOfStream\n\nDuring handling of the above exception, another exception occurred:\n\nTraceback (most recent call last):\n  File \"D:\\Vendor Management System\\backend\\app\\middleware\\logging_middleware.py\", line 29, in dispatch\n    response = await call_next(request)\n  File \"D:\\Vendor Management System\\backend\\venv\\lib\\site-packages\\starlette\\middleware\\base.py\", line 84, in call_next\n    raise app_exc\n  File \"D:\\Vendor Management System\\backend\\venv\\lib\\site-packages\\starlette\\middleware\\base.py\", line 70, in coro\n    await self.app(scope, receive_or_disconnect, send_no_error)\n  File \"D:\\Vendor Management System\\backend\\venv\\lib\\site-packages\\starlette\\middleware\\trustedhost.py\", line 51, in __call__\n    await self.app(scope, receive, send)\n  File \"D:\\Vendor Management System\\backend\\venv\\lib\\site-packages\\starlette\\middleware\\cors.py\", line 91, in __call__\n    await self.simple_response(scope, receive, send, request_headers=headers)\n  File \"D:\\Vendor Management System\\backend\\venv\\lib\\site-packages\\starlette\\middleware\\cors.py\", line 146, in simple_response\n    await self.app(scope, receive, send)\n  File \"D:\\Vendor Management System\\backend\\venv\\lib\\site-packages\\starlette\\middleware\\exceptions.py\", line 79, in __call__\n    raise exc\n  File \"D:\\Vendor Management System\\backend\\venv\\lib\\site-packages\\starlette\\middleware\\exceptions.py\", line 68, in __call__\n    await self.app(scope, receive, sender)\n  File \"D:\\Vendor Management System\\backend\\venv\\lib\\site-packages\\fastapi\\middleware\\asyncexitstack.py\", line 20, in __call__\n    raise e\n  File \"D:\\Vendor Management System\\backend\\venv\\lib\\site-packages\\fastapi\\middleware\\asyncexitstack.py\", line 17, in __call__\n    await self.app(scope, receive, send)\n  File \"D:\\Vendor Management System\\backend\\venv\\lib\\site-packages\\starlette\\routing.py\", line 718, in __call__\n    await route.handle(scope, receive, send)\n  File \"D:\\Vendor Management System\\backend\\venv\\lib\\site-packages\\starlette\\routing.py\", line 276, in handle\n    await self.app(scope, receive, send)\n  File \"D:\\Vendor Management System\\backend\\venv\\lib\\site-packages\\starlette\\routing.py\", line 66, in app\n    response = await func(request)\n  File \"D:\\Vendor Management System\\backend\\venv\\lib\\site-packages\\fastapi\\routing.py\", line 274, in app\n    raw_response = await run_endpoint_function(\n  File \"D:\\Vendor Management System\\backend\\venv\\lib\\site-packages\\fastapi\\routing.py\", line 191, in run_endpoint_function\n    return await dependant.call(**values)\n  File \"D:\\Vendor Management System\\backend\\app\\api\\vendors.py\", line 244, in get_vendor\n    from ..models.vendor_compliance import VendorCompliance\nModuleNotFoundError: No module named 'app.models.vendor_compliance'\n"
}
2025-08-07 16:22:30 | error | ERROR | Request Error: {
  "method": "GET",
  "url": "http://localhost:8000/api/v1/vendors/12",
  "error_type": "ModuleNotFoundError",
  "error_message": "No module named 'app.models.vendor_compliance'",
  "duration_ms": 25.73,
  "client_ip": "127.0.0.1",
  "user_id": null
}
2025-08-07 16:23:51 | error | ERROR | System Error: {
  "event_type": "SYSTEM_ERROR",
  "timestamp": "2025-08-07T10:53:51.795897",
  "error_type": "ModuleNotFoundError",
  "error_message": "No module named 'app.models.vendor_compliance'",
  "context": "Request: GET /api/v1/vendors/12",
  "user_id": null,
  "stack_trace": "Traceback (most recent call last):\n  File \"D:\\Vendor Management System\\backend\\venv\\lib\\site-packages\\anyio\\streams\\memory.py\", line 98, in receive\n    return self.receive_nowait()\n  File \"D:\\Vendor Management System\\backend\\venv\\lib\\site-packages\\anyio\\streams\\memory.py\", line 93, in receive_nowait\n    raise WouldBlock\nanyio.WouldBlock\n\nDuring handling of the above exception, another exception occurred:\n\nTraceback (most recent call last):\n  File \"D:\\Vendor Management System\\backend\\venv\\lib\\site-packages\\starlette\\middleware\\base.py\", line 78, in call_next\n    message = await recv_stream.receive()\n  File \"D:\\Vendor Management System\\backend\\venv\\lib\\site-packages\\anyio\\streams\\memory.py\", line 118, in receive\n    raise EndOfStream\nanyio.EndOfStream\n\nDuring handling of the above exception, another exception occurred:\n\nTraceback (most recent call last):\n  File \"D:\\Vendor Management System\\backend\\app\\middleware\\logging_middleware.py\", line 29, in dispatch\n    response = await call_next(request)\n  File \"D:\\Vendor Management System\\backend\\venv\\lib\\site-packages\\starlette\\middleware\\base.py\", line 84, in call_next\n    raise app_exc\n  File \"D:\\Vendor Management System\\backend\\venv\\lib\\site-packages\\starlette\\middleware\\base.py\", line 70, in coro\n    await self.app(scope, receive_or_disconnect, send_no_error)\n  File \"D:\\Vendor Management System\\backend\\venv\\lib\\site-packages\\starlette\\middleware\\trustedhost.py\", line 51, in __call__\n    await self.app(scope, receive, send)\n  File \"D:\\Vendor Management System\\backend\\venv\\lib\\site-packages\\starlette\\middleware\\cors.py\", line 91, in __call__\n    await self.simple_response(scope, receive, send, request_headers=headers)\n  File \"D:\\Vendor Management System\\backend\\venv\\lib\\site-packages\\starlette\\middleware\\cors.py\", line 146, in simple_response\n    await self.app(scope, receive, send)\n  File \"D:\\Vendor Management System\\backend\\venv\\lib\\site-packages\\starlette\\middleware\\exceptions.py\", line 79, in __call__\n    raise exc\n  File \"D:\\Vendor Management System\\backend\\venv\\lib\\site-packages\\starlette\\middleware\\exceptions.py\", line 68, in __call__\n    await self.app(scope, receive, sender)\n  File \"D:\\Vendor Management System\\backend\\venv\\lib\\site-packages\\fastapi\\middleware\\asyncexitstack.py\", line 20, in __call__\n    raise e\n  File \"D:\\Vendor Management System\\backend\\venv\\lib\\site-packages\\fastapi\\middleware\\asyncexitstack.py\", line 17, in __call__\n    await self.app(scope, receive, send)\n  File \"D:\\Vendor Management System\\backend\\venv\\lib\\site-packages\\starlette\\routing.py\", line 718, in __call__\n    await route.handle(scope, receive, send)\n  File \"D:\\Vendor Management System\\backend\\venv\\lib\\site-packages\\starlette\\routing.py\", line 276, in handle\n    await self.app(scope, receive, send)\n  File \"D:\\Vendor Management System\\backend\\venv\\lib\\site-packages\\starlette\\routing.py\", line 66, in app\n    response = await func(request)\n  File \"D:\\Vendor Management System\\backend\\venv\\lib\\site-packages\\fastapi\\routing.py\", line 274, in app\n    raw_response = await run_endpoint_function(\n  File \"D:\\Vendor Management System\\backend\\venv\\lib\\site-packages\\fastapi\\routing.py\", line 191, in run_endpoint_function\n    return await dependant.call(**values)\n  File \"D:\\Vendor Management System\\backend\\app\\api\\vendors.py\", line 244, in get_vendor\n    from ..models.vendor_compliance import VendorCompliance\nModuleNotFoundError: No module named 'app.models.vendor_compliance'\n"
}
2025-08-07 16:23:51 | error | ERROR | Request Error: {
  "method": "GET",
  "url": "http://localhost:8000/api/v1/vendors/12",
  "error_type": "ModuleNotFoundError",
  "error_message": "No module named 'app.models.vendor_compliance'",
  "duration_ms": 36.26,
  "client_ip": "127.0.0.1",
  "user_id": null
}
2025-08-07 16:23:55 | error | ERROR | System Error: {
  "event_type": "SYSTEM_ERROR",
  "timestamp": "2025-08-07T10:53:55.652783",
  "error_type": "ModuleNotFoundError",
  "error_message": "No module named 'app.models.vendor_compliance'",
  "context": "Request: GET /api/v1/vendors/12",
  "user_id": null,
  "stack_trace": "Traceback (most recent call last):\n  File \"D:\\Vendor Management System\\backend\\venv\\lib\\site-packages\\anyio\\streams\\memory.py\", line 98, in receive\n    return self.receive_nowait()\n  File \"D:\\Vendor Management System\\backend\\venv\\lib\\site-packages\\anyio\\streams\\memory.py\", line 93, in receive_nowait\n    raise WouldBlock\nanyio.WouldBlock\n\nDuring handling of the above exception, another exception occurred:\n\nTraceback (most recent call last):\n  File \"D:\\Vendor Management System\\backend\\venv\\lib\\site-packages\\starlette\\middleware\\base.py\", line 78, in call_next\n    message = await recv_stream.receive()\n  File \"D:\\Vendor Management System\\backend\\venv\\lib\\site-packages\\anyio\\streams\\memory.py\", line 118, in receive\n    raise EndOfStream\nanyio.EndOfStream\n\nDuring handling of the above exception, another exception occurred:\n\nTraceback (most recent call last):\n  File \"D:\\Vendor Management System\\backend\\app\\middleware\\logging_middleware.py\", line 29, in dispatch\n    response = await call_next(request)\n  File \"D:\\Vendor Management System\\backend\\venv\\lib\\site-packages\\starlette\\middleware\\base.py\", line 84, in call_next\n    raise app_exc\n  File \"D:\\Vendor Management System\\backend\\venv\\lib\\site-packages\\starlette\\middleware\\base.py\", line 70, in coro\n    await self.app(scope, receive_or_disconnect, send_no_error)\n  File \"D:\\Vendor Management System\\backend\\venv\\lib\\site-packages\\starlette\\middleware\\trustedhost.py\", line 51, in __call__\n    await self.app(scope, receive, send)\n  File \"D:\\Vendor Management System\\backend\\venv\\lib\\site-packages\\starlette\\middleware\\cors.py\", line 91, in __call__\n    await self.simple_response(scope, receive, send, request_headers=headers)\n  File \"D:\\Vendor Management System\\backend\\venv\\lib\\site-packages\\starlette\\middleware\\cors.py\", line 146, in simple_response\n    await self.app(scope, receive, send)\n  File \"D:\\Vendor Management System\\backend\\venv\\lib\\site-packages\\starlette\\middleware\\exceptions.py\", line 79, in __call__\n    raise exc\n  File \"D:\\Vendor Management System\\backend\\venv\\lib\\site-packages\\starlette\\middleware\\exceptions.py\", line 68, in __call__\n    await self.app(scope, receive, sender)\n  File \"D:\\Vendor Management System\\backend\\venv\\lib\\site-packages\\fastapi\\middleware\\asyncexitstack.py\", line 20, in __call__\n    raise e\n  File \"D:\\Vendor Management System\\backend\\venv\\lib\\site-packages\\fastapi\\middleware\\asyncexitstack.py\", line 17, in __call__\n    await self.app(scope, receive, send)\n  File \"D:\\Vendor Management System\\backend\\venv\\lib\\site-packages\\starlette\\routing.py\", line 718, in __call__\n    await route.handle(scope, receive, send)\n  File \"D:\\Vendor Management System\\backend\\venv\\lib\\site-packages\\starlette\\routing.py\", line 276, in handle\n    await self.app(scope, receive, send)\n  File \"D:\\Vendor Management System\\backend\\venv\\lib\\site-packages\\starlette\\routing.py\", line 66, in app\n    response = await func(request)\n  File \"D:\\Vendor Management System\\backend\\venv\\lib\\site-packages\\fastapi\\routing.py\", line 274, in app\n    raw_response = await run_endpoint_function(\n  File \"D:\\Vendor Management System\\backend\\venv\\lib\\site-packages\\fastapi\\routing.py\", line 191, in run_endpoint_function\n    return await dependant.call(**values)\n  File \"D:\\Vendor Management System\\backend\\app\\api\\vendors.py\", line 244, in get_vendor\n    from ..models.vendor_compliance import VendorCompliance\nModuleNotFoundError: No module named 'app.models.vendor_compliance'\n"
}
2025-08-07 16:23:55 | error | ERROR | Request Error: {
  "method": "GET",
  "url": "http://localhost:8000/api/v1/vendors/12",
  "error_type": "ModuleNotFoundError",
  "error_message": "No module named 'app.models.vendor_compliance'",
  "duration_ms": 17.37,
  "client_ip": "127.0.0.1",
  "user_id": null
}
2025-08-07 16:35:00 | error | WARNING | Error response: {
  "method": "POST",
  "url": "http://localhost:8000/api/v1/vendors/12/compliance-certificates",
  "status_code": 401,
  "duration_ms": 2.0,
  "client_ip": "127.0.0.1",
  "user_id": null
}
2025-08-07 16:35:11 | error | WARNING | Error response: {
  "method": "GET",
  "url": "http://localhost:8000/api/v1/vendors/12/compliance-certificates",
  "status_code": 401,
  "duration_ms": 2.0,
  "client_ip": "127.0.0.1",
  "user_id": null
}
2025-08-07 16:35:33 | error | WARNING | Error response: {
  "method": "GET",
  "url": "http://localhost:8000/api/v1/vendors/12/compliance-certificates",
  "status_code": 403,
  "duration_ms": 2.58,
  "client_ip": "127.0.0.1",
  "user_id": null
}
2025-08-07 16:35:41 | error | WARNING | Error response: {
  "method": "GET",
  "url": "http://localhost:8000/api/v1/vendors/12/compliance-certificates",
  "status_code": 403,
  "duration_ms": 2.0,
  "client_ip": "127.0.0.1",
  "user_id": null
}
2025-08-07 16:36:36 | error | WARNING | Error response: {
  "method": "GET",
  "url": "http://localhost:8000/api/v1/vendors/12/compliance-certificates",
  "status_code": 403,
  "duration_ms": 5.01,
  "client_ip": "127.0.0.1",
  "user_id": null
}
2025-08-07 17:14:07 | error | WARNING | Error response: {
  "method": "GET",
  "url": "http://localhost:8000/api/v1/auth/me",
  "status_code": 401,
  "duration_ms": 5.99,
  "client_ip": "127.0.0.1",
  "user_id": null
}
2025-08-07 18:02:08 | error | WARNING | Error response: {
  "method": "GET",
  "url": "http://localhost:8000/api/v1/auth/me",
  "status_code": 401,
  "duration_ms": 4.03,
  "client_ip": "127.0.0.1",
  "user_id": null
}
2025-08-07 18:02:22 | error | WARNING | Error response: {
  "method": "POST",
  "url": "http://localhost:8000/api/v1/vendors/public-registration",
  "status_code": 422,
  "duration_ms": 5.28,
  "client_ip": "127.0.0.1",
  "user_id": null
}
2025-08-07 18:06:06 | error | WARNING | Error response: {
  "method": "POST",
  "url": "http://localhost:8000/api/v1/vendors/public-registration",
  "status_code": 422,
  "duration_ms": 5.01,
  "client_ip": "127.0.0.1",
  "user_id": null
}
2025-08-07 18:06:36 | error | WARNING | Error response: {
  "method": "POST",
  "url": "http://localhost:8000/api/v1/vendors/public-registration",
  "status_code": 422,
  "duration_ms": 19.05,
  "client_ip": "127.0.0.1",
  "user_id": null
}
2025-08-07 18:07:07 | error | WARNING | Error response: {
  "method": "POST",
  "url": "http://localhost:8000/api/v1/vendors/public-registration",
  "status_code": 422,
  "duration_ms": 4.01,
  "client_ip": "127.0.0.1",
  "user_id": null
}
2025-08-07 18:07:10 | error | WARNING | Error response: {
  "method": "POST",
  "url": "http://localhost:8000/api/v1/vendors/public-registration",
  "status_code": 422,
  "duration_ms": 4.0,
  "client_ip": "127.0.0.1",
  "user_id": null
}
2025-08-07 18:07:11 | error | WARNING | Error response: {
  "method": "POST",
  "url": "http://localhost:8000/api/v1/vendors/public-registration",
  "status_code": 422,
  "duration_ms": 3.01,
  "client_ip": "127.0.0.1",
  "user_id": null
}
2025-08-07 18:07:25 | error | WARNING | Error response: {
  "method": "POST",
  "url": "http://localhost:8000/api/v1/vendors/public-registration",
  "status_code": 422,
  "duration_ms": 3.0,
  "client_ip": "127.0.0.1",
  "user_id": null
}
2025-08-07 18:09:22 | error | WARNING | Error response: {
  "method": "POST",
  "url": "http://localhost:8000/api/v1/vendors/public-registration",
  "status_code": 422,
  "duration_ms": 4.01,
  "client_ip": "127.0.0.1",
  "user_id": null
}
2025-08-07 18:12:19 | error | WARNING | Error response: {
  "method": "POST",
  "url": "http://localhost:8000/api/v1/vendors/public-registration",
  "status_code": 422,
  "duration_ms": 4.0,
  "client_ip": "127.0.0.1",
  "user_id": null
}
2025-08-07 18:12:20 | error | WARNING | Error response: {
  "method": "POST",
  "url": "http://localhost:8000/api/v1/vendors/public-registration",
  "status_code": 422,
  "duration_ms": 3.0,
  "client_ip": "127.0.0.1",
  "user_id": null
}
2025-08-07 18:12:35 | error | WARNING | Error response: {
  "method": "POST",
  "url": "http://localhost:8000/api/v1/vendors/public-registration",
  "status_code": 422,
  "duration_ms": 2.0,
  "client_ip": "127.0.0.1",
  "user_id": null
}
2025-08-07 18:14:39 | error | WARNING | Error response: {
  "method": "POST",
  "url": "http://localhost:8000/api/v1/vendors/public-registration",
  "status_code": 422,
  "duration_ms": 3.02,
  "client_ip": "127.0.0.1",
  "user_id": null
}
2025-08-07 18:56:05 | error | ERROR | System Error: {
  "event_type": "SYSTEM_ERROR",
  "timestamp": "2025-08-07T13:26:05.566050",
  "error_type": "AttributeError",
  "error_message": "'Vendor' object has no attribute 'registration_date'",
  "context": "Request: POST /api/v1/vendors/14/registration-agreement-pdf",
  "user_id": null,
  "stack_trace": "Traceback (most recent call last):\n  File \"D:\\Vendor Management System\\backend\\venv\\lib\\site-packages\\anyio\\streams\\memory.py\", line 98, in receive\n    return self.receive_nowait()\n  File \"D:\\Vendor Management System\\backend\\venv\\lib\\site-packages\\anyio\\streams\\memory.py\", line 93, in receive_nowait\n    raise WouldBlock\nanyio.WouldBlock\n\nDuring handling of the above exception, another exception occurred:\n\nTraceback (most recent call last):\n  File \"D:\\Vendor Management System\\backend\\venv\\lib\\site-packages\\starlette\\middleware\\base.py\", line 78, in call_next\n    message = await recv_stream.receive()\n  File \"D:\\Vendor Management System\\backend\\venv\\lib\\site-packages\\anyio\\streams\\memory.py\", line 118, in receive\n    raise EndOfStream\nanyio.EndOfStream\n\nDuring handling of the above exception, another exception occurred:\n\nTraceback (most recent call last):\n  File \"D:\\Vendor Management System\\backend\\app\\middleware\\logging_middleware.py\", line 29, in dispatch\n    response = await call_next(request)\n  File \"D:\\Vendor Management System\\backend\\venv\\lib\\site-packages\\starlette\\middleware\\base.py\", line 84, in call_next\n    raise app_exc\n  File \"D:\\Vendor Management System\\backend\\venv\\lib\\site-packages\\starlette\\middleware\\base.py\", line 70, in coro\n    await self.app(scope, receive_or_disconnect, send_no_error)\n  File \"D:\\Vendor Management System\\backend\\venv\\lib\\site-packages\\starlette\\middleware\\trustedhost.py\", line 51, in __call__\n    await self.app(scope, receive, send)\n  File \"D:\\Vendor Management System\\backend\\venv\\lib\\site-packages\\starlette\\middleware\\cors.py\", line 91, in __call__\n    await self.simple_response(scope, receive, send, request_headers=headers)\n  File \"D:\\Vendor Management System\\backend\\venv\\lib\\site-packages\\starlette\\middleware\\cors.py\", line 146, in simple_response\n    await self.app(scope, receive, send)\n  File \"D:\\Vendor Management System\\backend\\venv\\lib\\site-packages\\starlette\\middleware\\exceptions.py\", line 79, in __call__\n    raise exc\n  File \"D:\\Vendor Management System\\backend\\venv\\lib\\site-packages\\starlette\\middleware\\exceptions.py\", line 68, in __call__\n    await self.app(scope, receive, sender)\n  File \"D:\\Vendor Management System\\backend\\venv\\lib\\site-packages\\fastapi\\middleware\\asyncexitstack.py\", line 20, in __call__\n    raise e\n  File \"D:\\Vendor Management System\\backend\\venv\\lib\\site-packages\\fastapi\\middleware\\asyncexitstack.py\", line 17, in __call__\n    await self.app(scope, receive, send)\n  File \"D:\\Vendor Management System\\backend\\venv\\lib\\site-packages\\starlette\\routing.py\", line 718, in __call__\n    await route.handle(scope, receive, send)\n  File \"D:\\Vendor Management System\\backend\\venv\\lib\\site-packages\\starlette\\routing.py\", line 276, in handle\n    await self.app(scope, receive, send)\n  File \"D:\\Vendor Management System\\backend\\venv\\lib\\site-packages\\starlette\\routing.py\", line 66, in app\n    response = await func(request)\n  File \"D:\\Vendor Management System\\backend\\venv\\lib\\site-packages\\fastapi\\routing.py\", line 274, in app\n    raw_response = await run_endpoint_function(\n  File \"D:\\Vendor Management System\\backend\\venv\\lib\\site-packages\\fastapi\\routing.py\", line 191, in run_endpoint_function\n    return await dependant.call(**values)\n  File \"D:\\Vendor Management System\\backend\\app\\api\\vendors.py\", line 1627, in download_registration_agreement_pdf\n    ['Signed Date', vendor.registration_date.strftime('%d/%m/%Y') if vendor.registration_date else 'N/A'],\nAttributeError: 'Vendor' object has no attribute 'registration_date'\n"
}
2025-08-07 18:56:05 | error | ERROR | Request Error: {
  "method": "POST",
  "url": "http://localhost:8000/api/v1/vendors/14/registration-agreement-pdf",
  "error_type": "AttributeError",
  "error_message": "'Vendor' object has no attribute 'registration_date'",
  "duration_ms": 761.51,
  "client_ip": "127.0.0.1",
  "user_id": null
}
2025-08-07 18:56:10 | error | ERROR | System Error: {
  "event_type": "SYSTEM_ERROR",
  "timestamp": "2025-08-07T13:26:10.470230",
  "error_type": "AttributeError",
  "error_message": "'Vendor' object has no attribute 'registration_date'",
  "context": "Request: POST /api/v1/vendors/14/registration-agreement-pdf",
  "user_id": null,
  "stack_trace": "Traceback (most recent call last):\n  File \"D:\\Vendor Management System\\backend\\venv\\lib\\site-packages\\anyio\\streams\\memory.py\", line 98, in receive\n    return self.receive_nowait()\n  File \"D:\\Vendor Management System\\backend\\venv\\lib\\site-packages\\anyio\\streams\\memory.py\", line 93, in receive_nowait\n    raise WouldBlock\nanyio.WouldBlock\n\nDuring handling of the above exception, another exception occurred:\n\nTraceback (most recent call last):\n  File \"D:\\Vendor Management System\\backend\\venv\\lib\\site-packages\\starlette\\middleware\\base.py\", line 78, in call_next\n    message = await recv_stream.receive()\n  File \"D:\\Vendor Management System\\backend\\venv\\lib\\site-packages\\anyio\\streams\\memory.py\", line 118, in receive\n    raise EndOfStream\nanyio.EndOfStream\n\nDuring handling of the above exception, another exception occurred:\n\nTraceback (most recent call last):\n  File \"D:\\Vendor Management System\\backend\\app\\middleware\\logging_middleware.py\", line 29, in dispatch\n    response = await call_next(request)\n  File \"D:\\Vendor Management System\\backend\\venv\\lib\\site-packages\\starlette\\middleware\\base.py\", line 84, in call_next\n    raise app_exc\n  File \"D:\\Vendor Management System\\backend\\venv\\lib\\site-packages\\starlette\\middleware\\base.py\", line 70, in coro\n    await self.app(scope, receive_or_disconnect, send_no_error)\n  File \"D:\\Vendor Management System\\backend\\venv\\lib\\site-packages\\starlette\\middleware\\trustedhost.py\", line 51, in __call__\n    await self.app(scope, receive, send)\n  File \"D:\\Vendor Management System\\backend\\venv\\lib\\site-packages\\starlette\\middleware\\cors.py\", line 91, in __call__\n    await self.simple_response(scope, receive, send, request_headers=headers)\n  File \"D:\\Vendor Management System\\backend\\venv\\lib\\site-packages\\starlette\\middleware\\cors.py\", line 146, in simple_response\n    await self.app(scope, receive, send)\n  File \"D:\\Vendor Management System\\backend\\venv\\lib\\site-packages\\starlette\\middleware\\exceptions.py\", line 79, in __call__\n    raise exc\n  File \"D:\\Vendor Management System\\backend\\venv\\lib\\site-packages\\starlette\\middleware\\exceptions.py\", line 68, in __call__\n    await self.app(scope, receive, sender)\n  File \"D:\\Vendor Management System\\backend\\venv\\lib\\site-packages\\fastapi\\middleware\\asyncexitstack.py\", line 20, in __call__\n    raise e\n  File \"D:\\Vendor Management System\\backend\\venv\\lib\\site-packages\\fastapi\\middleware\\asyncexitstack.py\", line 17, in __call__\n    await self.app(scope, receive, send)\n  File \"D:\\Vendor Management System\\backend\\venv\\lib\\site-packages\\starlette\\routing.py\", line 718, in __call__\n    await route.handle(scope, receive, send)\n  File \"D:\\Vendor Management System\\backend\\venv\\lib\\site-packages\\starlette\\routing.py\", line 276, in handle\n    await self.app(scope, receive, send)\n  File \"D:\\Vendor Management System\\backend\\venv\\lib\\site-packages\\starlette\\routing.py\", line 66, in app\n    response = await func(request)\n  File \"D:\\Vendor Management System\\backend\\venv\\lib\\site-packages\\fastapi\\routing.py\", line 274, in app\n    raw_response = await run_endpoint_function(\n  File \"D:\\Vendor Management System\\backend\\venv\\lib\\site-packages\\fastapi\\routing.py\", line 191, in run_endpoint_function\n    return await dependant.call(**values)\n  File \"D:\\Vendor Management System\\backend\\app\\api\\vendors.py\", line 1627, in download_registration_agreement_pdf\n    ['Signed Date', vendor.registration_date.strftime('%d/%m/%Y') if vendor.registration_date else 'N/A'],\nAttributeError: 'Vendor' object has no attribute 'registration_date'\n"
}
2025-08-07 18:56:10 | error | ERROR | Request Error: {
  "method": "POST",
  "url": "http://localhost:8000/api/v1/vendors/14/registration-agreement-pdf",
  "error_type": "AttributeError",
  "error_message": "'Vendor' object has no attribute 'registration_date'",
  "duration_ms": 6.02,
  "client_ip": "127.0.0.1",
  "user_id": null
}
2025-08-07 18:56:14 | error | ERROR | System Error: {
  "event_type": "SYSTEM_ERROR",
  "timestamp": "2025-08-07T13:26:14.137243",
  "error_type": "AttributeError",
  "error_message": "'Vendor' object has no attribute 'registration_date'",
  "context": "Request: POST /api/v1/vendors/14/registration-agreement-pdf",
  "user_id": null,
  "stack_trace": "Traceback (most recent call last):\n  File \"D:\\Vendor Management System\\backend\\venv\\lib\\site-packages\\anyio\\streams\\memory.py\", line 98, in receive\n    return self.receive_nowait()\n  File \"D:\\Vendor Management System\\backend\\venv\\lib\\site-packages\\anyio\\streams\\memory.py\", line 93, in receive_nowait\n    raise WouldBlock\nanyio.WouldBlock\n\nDuring handling of the above exception, another exception occurred:\n\nTraceback (most recent call last):\n  File \"D:\\Vendor Management System\\backend\\venv\\lib\\site-packages\\starlette\\middleware\\base.py\", line 78, in call_next\n    message = await recv_stream.receive()\n  File \"D:\\Vendor Management System\\backend\\venv\\lib\\site-packages\\anyio\\streams\\memory.py\", line 118, in receive\n    raise EndOfStream\nanyio.EndOfStream\n\nDuring handling of the above exception, another exception occurred:\n\nTraceback (most recent call last):\n  File \"D:\\Vendor Management System\\backend\\app\\middleware\\logging_middleware.py\", line 29, in dispatch\n    response = await call_next(request)\n  File \"D:\\Vendor Management System\\backend\\venv\\lib\\site-packages\\starlette\\middleware\\base.py\", line 84, in call_next\n    raise app_exc\n  File \"D:\\Vendor Management System\\backend\\venv\\lib\\site-packages\\starlette\\middleware\\base.py\", line 70, in coro\n    await self.app(scope, receive_or_disconnect, send_no_error)\n  File \"D:\\Vendor Management System\\backend\\venv\\lib\\site-packages\\starlette\\middleware\\trustedhost.py\", line 51, in __call__\n    await self.app(scope, receive, send)\n  File \"D:\\Vendor Management System\\backend\\venv\\lib\\site-packages\\starlette\\middleware\\cors.py\", line 91, in __call__\n    await self.simple_response(scope, receive, send, request_headers=headers)\n  File \"D:\\Vendor Management System\\backend\\venv\\lib\\site-packages\\starlette\\middleware\\cors.py\", line 146, in simple_response\n    await self.app(scope, receive, send)\n  File \"D:\\Vendor Management System\\backend\\venv\\lib\\site-packages\\starlette\\middleware\\exceptions.py\", line 79, in __call__\n    raise exc\n  File \"D:\\Vendor Management System\\backend\\venv\\lib\\site-packages\\starlette\\middleware\\exceptions.py\", line 68, in __call__\n    await self.app(scope, receive, sender)\n  File \"D:\\Vendor Management System\\backend\\venv\\lib\\site-packages\\fastapi\\middleware\\asyncexitstack.py\", line 20, in __call__\n    raise e\n  File \"D:\\Vendor Management System\\backend\\venv\\lib\\site-packages\\fastapi\\middleware\\asyncexitstack.py\", line 17, in __call__\n    await self.app(scope, receive, send)\n  File \"D:\\Vendor Management System\\backend\\venv\\lib\\site-packages\\starlette\\routing.py\", line 718, in __call__\n    await route.handle(scope, receive, send)\n  File \"D:\\Vendor Management System\\backend\\venv\\lib\\site-packages\\starlette\\routing.py\", line 276, in handle\n    await self.app(scope, receive, send)\n  File \"D:\\Vendor Management System\\backend\\venv\\lib\\site-packages\\starlette\\routing.py\", line 66, in app\n    response = await func(request)\n  File \"D:\\Vendor Management System\\backend\\venv\\lib\\site-packages\\fastapi\\routing.py\", line 274, in app\n    raw_response = await run_endpoint_function(\n  File \"D:\\Vendor Management System\\backend\\venv\\lib\\site-packages\\fastapi\\routing.py\", line 191, in run_endpoint_function\n    return await dependant.call(**values)\n  File \"D:\\Vendor Management System\\backend\\app\\api\\vendors.py\", line 1627, in download_registration_agreement_pdf\n    ['Signed Date', vendor.registration_date.strftime('%d/%m/%Y') if vendor.registration_date else 'N/A'],\nAttributeError: 'Vendor' object has no attribute 'registration_date'\n"
}
2025-08-07 18:56:14 | error | ERROR | Request Error: {
  "method": "POST",
  "url": "http://localhost:8000/api/v1/vendors/14/registration-agreement-pdf",
  "error_type": "AttributeError",
  "error_message": "'Vendor' object has no attribute 'registration_date'",
  "duration_ms": 6.71,
  "client_ip": "127.0.0.1",
  "user_id": null
}
2025-08-07 19:05:20 | error | WARNING | Error response: {
  "method": "GET",
  "url": "http://localhost:8000/api/v1/auth/me",
  "status_code": 401,
  "duration_ms": 2.52,
  "client_ip": "127.0.0.1",
  "user_id": null
}
2025-08-07 20:16:52 | error | WARNING | Error response: {
  "method": "GET",
  "url": "http://localhost:8000/api/v1/auth/me",
  "status_code": 401,
  "duration_ms": 0.0,
  "client_ip": "127.0.0.1",
  "user_id": null
}
